Workbook

Sheet 안내
A1: 항목 | B1: 설명
A2: 이 파일 | B2: 여유로 서울 1~9호선 벡터 노선도 좌표의 기본 파일(source of truth). 2026-10 v2.6 에서 처음부터 다시 정리.
A3: 좌표계 | B3: 캔버스 5120 × 2880 px, 원점 왼쪽 위, y 는 아래로 증가. pct 는 px 에서 계산한 값(수식 아님).
A4: 핵심 원칙 | B4: 사용자 선택 = station_key / 지도 그리기 = visual_node_id / 경로 계산 = station_uid (9호선은 9L·9X). 세 계층을 섞지 않는다.
A5: Lines | B5: 노선 목록·색·범위. 색을 바꾸려면 여기와 가져오기 스크립트의 LINE_COLORS 를 같이 바꾼다.
A6: Station_Display_Master | B6: 역 단위 목록 270개. 사용자가 고르는 역. candidate_station_uids 는 가져오기 스크립트가 채운다.
A7: Station_Visual_Nodes | B7: 노선별 역 점 좌표 315개 (1→9호선, 노선 순서). 환승역은 노선마다 점이 따로 있고, 같은 역의 점은 겹쳐도 된다.
A8: Line_Sequences | B8: 노선을 그리는 순서. visual_node_id 를 path_order 대로 잇는다.
A9: Transfer_Links | B9: 환승역 안에서 노선별 점을 잇는 회색 연결선 (보이는 선일 뿐, 환승 시간 계산과 무관).
A10: Station_Click_Areas | B10: 클릭 판정용 투명 원. 역당 1개.
A11: Station_Labels | B11: 역명 위치. 역당 1개. 겹치면 label_x_px / label_y_px 만 고친다.
A12: 수정 방법 | B12: 좌표를 고치면 x_px, y_px 만 바꾼다 (pct 는 가져오기 때 다시 계산됨). 새 역을 넣으면 Visual_Nodes·Line_Sequences·Display_Master·Click·Labels 에 같이 넣는다.
... A16: 실시간 연동 (v2.6) | B16: 노란 칸만 고친다. Station_Visual_Nodes 의 x_px·y_px 를 고치면 역명·클릭 위치(회색, 수식)가 바로 따라온다. 역명만 옮기려면 Station_Labels 의 label_dx·label_dy(이동량)를 고친다. 다른 역과 좌표가 같은 행은 주황색으로 바로 표시된다. 미리보기: python scripts/v2/29_watch_map.py 를 켜 두면 저장할 때마다 브라우저 미리보기가 새로고침된다.

Sheet Config
A1: parameter | B1: value | C1: note
A2: image_width_px | B2: 5120 | C2: 원본/작업 기준 이미지 가로 픽셀. x_pct 계산 기준
A3: image_height_px | B3: 2880 | C3: 원본/작업 기준 이미지 세로 픽셀. y_pct 계산 기준
A4: default_general_marker_radius_px | B4: 10 | C4: 지도에 보이는 일반역 원 반경
A5: default_transfer_marker_radius_px | B5: 12 | C5: 지도에 보이는 환승역 visual node 반경
A6: default_general_click_radius_px | B6: 24 | C6: 일반역 클릭 hitbox 반경
A7: default_transfer_click_radius_px | B7: 48 | C7: 2개 노선 환승역 클릭 hitbox 반경
A8: default_complex_transfer_click_radius_px | B8: 56 | C8: 3개 이상 노선 환승역 클릭 hitbox 반경
A9: coordinate_origin | B9: top-left | C9: 좌표 원점은 이미지 좌상단
A10: coordinate_unit | B10: pixel | C10: x_px, y_px는 픽셀 기준. x_pct, y_pct는 자동 계산
A11: final_render_target | B11: SVG or Plotly vector map | C11: PNG 배경이 아니라 좌표 기반 벡터 렌더링에도 사용 가능

Sheet Lines
A1: line_id | B1: line_name | C1: color | D1: project_range | E1: branch_codes | F1: note
A2: 1 | B2: 1호선 | C2: #0052A4 | D2: 서울역~청량리 | E2: main | F2: 서울교통공사 구간
A3: 2 | B3: 2호선 | C3: #009D3E | D3: 순환선 전 구간 + 성수지선 + 신정지선 | E3: main; seongsu_branch; sinjeong_branch | F3: 순환선은 렌더링 시 마지막→처음 연결
A4: 3 | B4: 3호선 | C4: #EF7C1C | D4: 지축~오금 | E4: main
A5: 4 | B5: 4호선 | C5: #00A5DE | D5: 불암산~남태령 | E5: main
A6: 5 | B6: 5호선 | C6: #996CAC | D6: 방화~하남검단산, 강동~마천 | E6: common; hanam_branch; macheon_branch | F6: 강동에서 분기
A7: 6 | B7: 6호선 | C7: #CD7C2F | D7: 응암~신내 (응암순환 포함) | E7: main | F7: 응암순환은 단방향
A8: 7 | B8: 7호선 | C8: #747F00 | D8: 장암~온수 | E8: main
A9: 8 | B9: 8호선 | C9: #E6186C | D9: 암사역사공원~모란 | E9: main
A10: 9 | B10: 9호선 | C10: #BDB092 | D10: 개화~중앙보훈병원 | E10: main | F10: 노선도는 한 줄. 일반/급행 구분은 경로 계산(9L/9X)에서만 사용

Sheet Station_Display_Master
A1: station_no | B1: station_key | C1: station_name | D1: display_name | E1: available_lines | F1: candidate_station_uids | G1: project_branches | H1: is_transfer_station | I1: is_event_station | J1: alias_or_note | K1: memo
A2: 1 | B2: 서울역 | C2: 서울역 | D2: 서울역 | E2: 1,4 | G2: 1:main;4:main | H2: TRUE | I2: FALSE
A3: 2 | B3: 시청 | C3: 시청 | D3: 시청역 | E3: 1,2 | G3: 1:main;2:main | H3: TRUE | I3: TRUE
A4: 3 | B4: 종각 | C4: 종각 | D4: 종각역 | E4: 1 | G4: 1:main | H4: FALSE | I4: TRUE
A5: 4 | B5: 종로3가 | C5: 종로3가 | D5: 종로3가역 | E5: 1,3,5 | G5: 1:main;3:main;5:common | H5: TRUE | I5: FALSE
A6: 5 | B6: 종로5가 | C6: 종로5가 | D6: 종로5가역 | E6: 1 | G6: 1:main | H6: FALSE | I6: FALSE
A7: 6 | B7: 동대문 | C7: 동대문 | D7: 동대문역 | E7: 1,4 | G7: 1:main;4:main | H7: TRUE | I7: FALSE
A8: 7 | B8: 동묘앞 | C8: 동묘앞 | D8: 동묘앞역 | E8: 1,6 | G8: 1:main;6:main | H8: TRUE | I8: FALSE
A9: 8 | B9: 신설동 | C9: 신설동 | D9: 신설동역 | E9: 1,2 | G9: 1:main;2:seongsu_branch | H9: TRUE | I9: FALSE
A10: 9 | B10: 제기동 | C10: 제기동 | D10: 제기동역 | E10: 1 | G10: 1:main | H10: FALSE | I10: FALSE
A11: 10 | B11: 청량리 | C11: 청량리 | D11: 청량리역 | E11: 1 | G11: 1:main | H11: FALSE | I11: FALSE | J11: 청량리(서울시립대입구)
A12: 11 | B12: 을지로입구 | C12: 을지로입구 | D12: 을지로입구역 | E12: 2 | G12: 2:main | H12: FALSE | I12: FALSE
A13: 12 | B13: 을지로3가 | C13: 을지로3가 | D13: 을지로3가역 | E13: 2,3 | G13: 2:main;3:main | H13: TRUE | I13: FALSE
A14: 13 | B14: 을지로4가 | C14: 을지로4가 | D14: 을지로4가역 | E14: 2,5 | G14: 2:main;5:common | H14: TRUE | I14: FALSE
A15: 14 | B15: 동대문역사문화공원 | C15: 동대문역사문화공원 | D15: 동대문역사문화공원역 | E15: 2,4,5 | G15: 2:main;4:main;5:common | H15: TRUE | I15: FALSE | J15: 동대문역사문화공원(DDP)
A16: 15 | B16: 신당 | C16: 신당 | D16: 신당역 | E16: 2,6 | G16: 2:main;6:main | H16: TRUE | I16: FALSE
A17: 16 | B17: 상왕십리 | C17: 상왕십리 | D17: 상왕십리역 | E17: 2 | G17: 2:main | H17: FALSE | I17: FALSE
A18: 17 | B18: 왕십리 | C18: 왕십리 | D18: 왕십리역 | E18: 2,5 | G18: 2:main;5:common | H18: TRUE | I18: FALSE
A19: 18 | B19: 한양대 | C19: 한양대 | D19: 한양대역 | E19: 2 | G19: 2:main | H19: FALSE | I19: TRUE
A20: 19 | B20: 뚝섬 | C20: 뚝섬 | D20: 뚝섬역 | E20: 2 | G20: 2:main | H20: FALSE | I20: FALSE
A21: 20 | B21: 성수 | C21: 성수 | D21: 성수역 | E21: 2 | G21: 2:main;2:seongsu_branch | H21: FALSE | I21: FALSE
A22: 21 | B22: 건대입구 | C22: 건대입구 | D22: 건대입구역 | E22: 2,7 | G22: 2:main;7:main | H22: TRUE | I22: TRUE
A23: 22 | B23: 구의 | C23: 구의 | D23: 구의역 | E23: 2 | G23: 2:main | H23: FALSE | I23: FALSE
A24: 23 | B24: 강변 | C24: 강변 | D24: 강변역 | E24: 2 | G24: 2:main | H24: FALSE | I24: FALSE
A25: 24 | B25: 잠실나루 | C25: 잠실나루 | D25: 잠실나루역 | E25: 2 | G25: 2:main | H25: FALSE | I25: FALSE
A26: 25 | B26: 잠실 | C26: 잠실 | D26: 잠실역 | E26: 2,8 | G26: 2:main;8:main | H26: TRUE | I26: FALSE
A27: 26 | B27: 잠실새내 | C27: 잠실새내 | D27: 잠실새내역 | E27: 2 | G27: 2:main | H27: FALSE | I27: FALSE
... A68: 67 | B68: 독립문 | C68: 독립문 | D68: 독립문역 | E68: 3 | G68: 3:main | H68: FALSE | I68: FALSE
A69: 68 | B69: 경복궁 | C69: 경복궁 | D69: 경복궁역 | E69: 3 | G69: 3:main | H69: FALSE | I69: TRUE | J69: 경복궁(정부서울청사)
A70: 69 | B70: 안국 | C70: 안국 | D70: 안국역 | E70: 3 | G70: 3:main | H70: FALSE | I70: FALSE
A71: 70 | B71: 충무로 | C71: 충무로 | D71: 충무로역 | E71: 3,4 | G71: 3:main;4:main | H71: TRUE | I71: FALSE
A72: 71 | B72: 동대입구 | C72: 동대입구 | D72: 동대입구역 | E72: 3 | G72: 3:main | H72: FALSE | I72: TRUE
A73: 72 | B73: 약수 | C73: 약수 | D73: 약수역 | E73: 3,6 | G73: 3:main;6:main | H73: TRUE | I73: FALSE
A74: 73 | B74: 금호 | C74: 금호 | D74: 금호역 | E74: 3 | G74: 3:main | H74: FALSE | I74: FALSE
A75: 74 | B75: 옥수 | C75: 옥수 | D75: 옥수역 | E75: 3 | G75: 3:main | H75: FALSE | I75: FALSE
A76: 75 | B76: 압구정 | C76: 압구정 | D76: 압구정역 | E76: 3 | G76: 3:main | H76: FALSE | I76: FALSE
A77: 76 | B77: 신사 | C77: 신사 | D77: 신사역 | E77: 3 | G77: 3:main | H77: FALSE | I77: FALSE
A78: 77 | B78: 잠원 | C78: 잠원 | D78: 잠원역 | E78: 3 | G78: 3:main | H78: FALSE | I78: FALSE
A79: 78 | B79: 고속터미널 | C79: 고속터미널 | D79: 고속터미널역 | E79: 3,7,9 | G79: 3:main;7:main;9:main | H79: TRUE | I79: FALSE
A80: 79 | B80: 남부터미널 | C80: 남부터미널 | D80: 남부터미널역 | E80: 3 | G80: 3:main | H80: FALSE | I80: FALSE
...

Sheet Station_Visual_Nodes
A1: mark_status | B1: visual_node_no | C1: visual_node_id | D1: station_key | E1: station_name | F1: display_name | G1: line_id | H1: branch_codes | I1: x_px | J1: y_px | K1: x_pct | L1: y_pct | M1: marker_radius_px | N1: is_transfer_station | O1: is_branch_node | P1: label_owner | Q1: alias_or_note | R1: memo
A2: 완료 | B2: 1 | C2: 서울역_L1 | D2: 서울역 | E2: 서울역 | F2: 서울역 | G2: 1 | H2: main | I2: 1916 | J2: 1308 | K2: =I2/5120*100 | L2: =J2/2880*100 | M2: 12 | N2: TRUE | O2: TRUE | P2: TRUE
A3: 완료 | B3: 2 | C3: 시청_L1 | D3: 시청 | E3: 시청 | F3: 시청역 | G3: 1 | H3: main | I3: 1916 | J3: 1144 | K3: =I3/5120*100 | L3: =J3/2880*100 | M3: 12 | N3: TRUE | O3: FALSE | P3: TRUE
A4: 완료 | B4: 3 | C4: 종각_L1 | D4: 종각 | E4: 종각 | F4: 종각역 | G4: 1 | H4: main | I4: 1916 | J4: 1048 | K4: =I4/5120*100 | L4: =J4/2880*100 | M4: 10 | N4: FALSE | O4: FALSE | P4: TRUE
A5: 완료 | B5: 4 | C5: 종로3가_L1 | D5: 종로3가 | E5: 종로3가 | F5: 종로3가역 | G5: 1 | H5: main | I5: 2084 | J5: 980 | K5: =I5/5120*100 | L5: =J5/2880*100 | M5: 12 | N5: TRUE | O5: FALSE | P5: TRUE
A6: 완료 | B6: 5 | C6: 종로5가_L1 | D6: 종로5가 | E6: 종로5가 | F6: 종로5가역 | G6: 1 | H6: main | I6: 2206 | J6: 980 | K6: =I6/5120*100 | L6: =J6/2880*100 | M6: 10 | N6: FALSE | O6: FALSE | P6: TRUE
A7: 완료 | B7: 6 | C7: 동대문_L1 | D7: 동대문 | E7: 동대문 | F7: 동대문역 | G7: 1 | H7: main | I7: 2328 | J7: 980 | K7: =I7/5120*100 | L7: =J7/2880*100 | M7: 12 | N7: TRUE | O7: FALSE | P7: TRUE
A8: 완료 | B8: 7 | C8: 동묘앞_L1 | D8: 동묘앞 | E8: 동묘앞 | F8: 동묘앞역 | G8: 1 | H8: main | I8: 2528 | J8: 980 | K8: =I8/5120*100 | L8: =J8/2880*100 | M8: 12 | N8: TRUE | O8: FALSE | P8: TRUE
A9: 완료 | B9: 8 | C9: 신설동_L1 | D9: 신설동 | E9: 신설동 | F9: 신설동역 | G9: 1 | H9: main | I9: 2712 | J9: 980 | K9: =I9/5120*100 | L9: =J9/2880*100 | M9: 12 | N9: TRUE | O9: FALSE | P9: TRUE
A10: 완료 | B10: 9 | C10: 제기동_L1 | D10: 제기동 | E10: 제기동 | F10: 제기동역 | G10: 1 | H10: main | I10: 2888 | J10: 980 | K10: =I10/5120*100 | L10: =J10/2880*100 | M10: 10 | N10: FALSE | O10: FALSE | P10: TRUE
A11: 완료 | B11: 10 | C11: 청량리_L1 | D11: 청량리 | E11: 청량리 | F11: 청량리역 | G11: 1 | H11: main | I11: 3064 | J11: 980 | K11: =I11/5120*100 | L11: =J11/2880*100 | M11: 10 | N11: FALSE | O11: TRUE | P11: TRUE | Q11: 청량리(서울시립대입구)
A12: 완료 | B12: 11 | C12: 시청_L2 | D12: 시청 | E12: 시청 | F12: 시청역 | G12: 2 | H12: main | I12: 1916 | J12: 1144 | K12: =I12/5120*100 | L12: =J12/2880*100 | M12: 12 | N12: TRUE | O12: TRUE | P12: FALSE
A13: 완료 | B13: 12 | C13: 을지로입구_L2 | D13: 을지로입구 | E13: 을지로입구 | F13: 을지로입구역 | G13: 2 | H13: main | I13: 2000 | J13: 1144 | K13: =I13/5120*100 | L13: =J13/2880*100 | M13: 10 | N13: FALSE | O13: FALSE | P13: TRUE
A14: 완료 | B14: 13 | C14: 을지로3가_L2 | D14: 을지로3가 | E14: 을지로3가 | F14: 을지로3가역 | G14: 2 | H14: main | I14: 2084 | J14: 1144 | K14: =I14/5120*100 | L14: =J14/2880*100 | M14: 12 | N14: TRUE | O14: FALSE | P14: TRUE
A15: 완료 | B15: 14 | C15: 을지로4가_L2 | D15: 을지로4가 | E15: 을지로4가 | F15: 을지로4가역 | G15: 2 | H15: main | I15: 2206 | J15: 1144 | K15: =I15/5120*100 | L15: =J15/2880*100 | M15: 12 | N15: TRUE | O15: FALSE | P15: TRUE
A16: 완료 | B16: 15 | C16: 동대문역사문화공원_L2 | D16: 동대문역사문화공원 | E16: 동대문역사문화공원 | F16: 동대문역사문화공원역 | G16: 2 | H16: main | I16: 2328 | J16: 1144 | K16: =I16/5120*100 | L16: =J16/2880*100 | M16: 12 | N16: TRUE | O16: FALSE | P16: TRUE | Q16: 동대문역사문화공원(DDP)
A17: 완료 | B17: 16 | C17: 신당_L2 | D17: 신당 | E17: 신당 | F17: 신당역 | G17: 2 | H17: main | I17: 2528 | J17: 1144 | K17: =I17/5120*100 | L17: =J17/2880*100 | M17: 12 | N17: TRUE | O17: FALSE | P17: TRUE
A18: 완료 | B18: 17 | C18: 상왕십리_L2 | D18: 상왕십리 | E18: 상왕십리 | F18: 상왕십리역 | G18: 2 | H18: main | I18: 2628 | J18: 1144 | K18: =I18/5120*100 | L18: =J18/2880*100 | M18: 10 | N18: FALSE | O18: FALSE | P18: TRUE
A19: 완료 | B19: 18 | C19: 왕십리_L2 | D19: 왕십리 | E19: 왕십리 | F19: 왕십리역 | G19: 2 | H19: main | I19: 2740 | J19: 1144 | K19: =I19/5120*100 | L19: =J19/2880*100 | M19: 12 | N19: TRUE | O19: FALSE | P19: TRUE
A20: 완료 | B20: 19 | C20: 한양대_L2 | D20: 한양대 | E20: 한양대 | F20: 한양대역 | G20: 2 | H20: main | I20: 2816 | J20: 1208 | K20: =I20/5120*100 | L20: =J20/2880*100 | M20: 10 | N20: FALSE | O20: FALSE | P20: TRUE
A21: 완료 | B21: 20 | C21: 뚝섬_L2 | D21: 뚝섬 | E21: 뚝섬 | F21: 뚝섬역 | G21: 2 | H21: main | I21: 2896 | J21: 1272 | K21: =I21/5120*100 | L21: =J21/2880*100 | M21: 10 | N21: FALSE | O21: FALSE | P21: TRUE
A22: 완료 | B22: 21 | C22: 성수_L2 | D22: 성수 | E22: 성수 | F22: 성수역 | G22: 2 | H22: main;seongsu_branch | I22: 2972 | J22: 1336 | K22: =I22/5120*100 | L22: =J22/2880*100 | M22: 10 | N22: FALSE | O22: TRUE | P22: TRUE
A23: 완료 | B23: 22 | C23: 건대입구_L2 | D23: 건대입구 | E23: 건대입구 | F23: 건대입구역 | G23: 2 | H23: main | I23: 2972 | J23: 1468 | K23: =I23/5120*100 | L23: =J23/2880*100 | M23: 12 | N23: TRUE | O23: FALSE | P23: TRUE
A24: 완료 | B24: 23 | C24: 구의_L2 | D24: 구의 | E24: 구의 | F24: 구의역 | G24: 2 | H24: main | I24: 2972 | J24: 1552 | K24: =I24/5120*100 | L24: =J24/2880*100 | M24: 10 | N24: FALSE | O24: FALSE | P24: TRUE
A25: 완료 | B25: 24 | C25: 강변_L2 | D25: 강변 | E25: 강변 | F25: 강변역 | G25: 2 | H25: main | I25: 2972 | J25: 1628 | K25: =I25/5120*100 | L25: =J25/2880*100 | M25: 10 | N25: FALSE | O25: FALSE | P25: TRUE
A26: 완료 | B26: 25 | C26: 잠실나루_L2 | D26: 잠실나루 | E26: 잠실나루 | F26: 잠실나루역 | G26: 2 | H26: main | I26: 2972 | J26: 1708 | K26: =I26/5120*100 | L26: =J26/2880*100 | M26: 10 | N26: FALSE | O26: FALSE | P26: TRUE
A27: 완료 | B27: 26 | C27: 잠실_L2 | D27: 잠실 | E27: 잠실 | F27: 잠실역 | G27: 2 | H27: main | I27: 2972 | J27: 1800 | K27: =I27/5120*100 | L27: =J27/2880*100 | M27: 12 | N27: TRUE | O27: FALSE | P27: TRUE
A28: 완료 | B28: 27 | C28: 잠실새내_L2 | D28: 잠실새내 | E28: 잠실새내 | F28: 잠실새내역 | G28: 2 | H28: main | I28: 2972 | J28: 1882 | K28: =I28/5120*100 | L28: =J28/2880*100 | M28: 10 | N28: FALSE | O28: FALSE | P28: TRUE
A29: 완료 | B29: 28 | C29: 종합운동장_L2 | D29: 종합운동장 | E29: 종합운동장 | F29: 종합운동장역 | G29: 2 | H29: main | I29: 2972 | J29: 1964 | K29: =I29/5120*100 | L29: =J29/2880*100 | M29: 10 | N29: FALSE | O29: FALSE | P29: TRUE | R29: 다른 역(봉은사)과 좌표가 같음 — 확인 필요
A30: 완료 | B30: 29 | C30: 삼성_L2 | D30: 삼성 | E30: 삼성 | F30: 삼성역 | G30: 2 | H30: main | I30: 2874 | J30: 2040 | K30: =I30/5120*100 | L30: =J30/2880*100 | M30: 10 | N30: FALSE | O30: FALSE | P30: TRUE
A31: 완료 | B31: 30 | C31: 선릉_L2 | D31: 선릉 | E31: 선릉 | F31: 선릉역 | G31: 2 | H31: main | I31: 2776 | J31: 2116 | K31: =I31/5120*100 | L31: =J31/2880*100 | M31: 10 | N31: FALSE | O31: FALSE | P31: TRUE
A32: 완료 | B32: 31 | C32: 역삼_L2 | D32: 역삼 | E32: 역삼 | F32: 역삼역 | G32: 2 | H32: main | I32: 2696 | J32: 2116 | K32: =I32/5120*100 | L32: =J32/2880*100 | M32: 10 | N32: FALSE | O32: FALSE | P32: TRUE
A33: 완료 | B33: 32 | C33: 강남_L2 | D33: 강남 | E33: 강남 | F33: 강남역 | G33: 2 | H33: main | I33: 2616 | J33: 2116 | K33: =I33/5120*100 | L33: =J33/2880*100 | M33: 10 | N33: FALSE | O33: FALSE | P33: TRUE
A34: 완료 | B34: 33 | C34: 교대_L2 | D34: 교대 | E34: 교대 | F34: 교대역 | G34: 2 | H34: main | I34: 2480 | J34: 2116 | K34: =I34/5120*100 | L34: =J34/2880*100 | M34: 12 | N34: TRUE | O34: FALSE | P34: TRUE
A35: 완료 | B35: 34 | C35: 서초_L2 | D35: 서초 | E35: 서초 | F35: 서초역 | G35: 2 | H35: main | I35: 2384 | J35: 2116 | K35: =I35/5120*100 | L35: =J35/2880*100 | M35: 10 | N35: FALSE | O35: FALSE | P35: TRUE
A36: 완료 | B36: 35 | C36: 방배_L2 | D36: 방배 | E36: 방배 | F36: 방배역 | G36: 2 | H36: main | I36: 2296 | J36: 2116 | K36: =I36/5120*100 | L36: =J36/2880*100 | M36: 10 | N36: FALSE | O36: FALSE | P36: TRUE
A37: 완료 | B37: 36 | C37: 사당_L2 | D37: 사당 | E37: 사당 | F37: 사당역 | G37: 2 | H37: main | I37: 2200 | J37: 2116 | K37: =I37/5120*100 | L37: =J37/2880*100 | M37: 12 | N37: TRUE | O37: FALSE | P37: TRUE
A38: 완료 | B38: 37 | C38: 낙성대_L2 | D38: 낙성대 | E38: 낙성대 | F38: 낙성대역 | G38: 2 | H38: main | I38: 2092 | J38: 2116 | K38: =I38/5120*100 | L38: =J38/2880*100 | M38: 10 | N38: FALSE | O38: FALSE | P38: TRUE
A39: 완료 | B39: 38 | C39: 서울대입구_L2 | D39: 서울대입구 | E39: 서울대입구 | F39: 서울대입구역 | G39: 2 | H39: main | I39: 1984 | J39: 2116 | K39: =I39/5120*100 | L39: =J39/2880*100 | M39: 10 | N39: FALSE | O39: FALSE | P39: TRUE
A40: 완료 | B40: 39 | C40: 봉천_L2 | D40: 봉천 | E40: 봉천 | F40: 봉천역 | G40: 2 | H40: main | I40: 1876 | J40: 2116 | K40: =I40/5120*100 | L40: =J40/2880*100 | M40: 10 | N40: FALSE | O40: FALSE | P40: TRUE
...

Sheet Line_Sequences
A1: line_id | B1: branch_code | C1: path_order | D1: visual_node_id | E1: station_key | F1: station_name | G1: display_name | H1: is_branch_endpoint | I1: alias_or_note
A2: 1 | B2: main | C2: 1 | D2: 서울역_L1 | E2: 서울역 | F2: 서울역 | G2: 서울역 | H2: TRUE
A3: 1 | B3: main | C3: 2 | D3: 시청_L1 | E3: 시청 | F3: 시청 | G3: 시청역 | H3: FALSE
A4: 1 | B4: main | C4: 3 | D4: 종각_L1 | E4: 종각 | F4: 종각 | G4: 종각역 | H4: FALSE
A5: 1 | B5: main | C5: 4 | D5: 종로3가_L1 | E5: 종로3가 | F5: 종로3가 | G5: 종로3가역 | H5: FALSE
A6: 1 | B6: main | C6: 5 | D6: 종로5가_L1 | E6: 종로5가 | F6: 종로5가 | G6: 종로5가역 | H6: FALSE
A7: 1 | B7: main | C7: 6 | D7: 동대문_L1 | E7: 동대문 | F7: 동대문 | G7: 동대문역 | H7: FALSE
A8: 1 | B8: main | C8: 7 | D8: 동묘앞_L1 | E8: 동묘앞 | F8: 동묘앞 | G8: 동묘앞역 | H8: FALSE
A9: 1 | B9: main | C9: 8 | D9: 신설동_L1 | E9: 신설동 | F9: 신설동 | G9: 신설동역 | H9: FALSE
A10: 1 | B10: main | C10: 9 | D10: 제기동_L1 | E10: 제기동 | F10: 제기동 | G10: 제기동역 | H10: FALSE
A11: 1 | B11: main | C11: 10 | D11: 청량리_L1 | E11: 청량리 | F11: 청량리 | G11: 청량리역 | H11: TRUE | I11: 청량리(서울시립대입구)
A12: 2 | B12: main | C12: 1 | D12: 시청_L2 | E12: 시청 | F12: 시청 | G12: 시청역 | H12: TRUE
A13: 2 | B13: main | C13: 2 | D13: 을지로입구_L2 | E13: 을지로입구 | F13: 을지로입구 | G13: 을지로입구역 | H13: FALSE
A14: 2 | B14: main | C14: 3 | D14: 을지로3가_L2 | E14: 을지로3가 | F14: 을지로3가 | G14: 을지로3가역 | H14: FALSE
A15: 2 | B15: main | C15: 4 | D15: 을지로4가_L2 | E15: 을지로4가 | F15: 을지로4가 | G15: 을지로4가역 | H15: FALSE
A16: 2 | B16: main | C16: 5 | D16: 동대문역사문화공원_L2 | E16: 동대문역사문화공원 | F16: 동대문역사문화공원 | G16: 동대문역사문화공원역 | H16: FALSE | I16: 동대문역사문화공원(DDP)
A17: 2 | B17: main | C17: 6 | D17: 신당_L2 | E17: 신당 | F17: 신당 | G17: 신당역 | H17: FALSE
A18: 2 | B18: main | C18: 7 | D18: 상왕십리_L2 | E18: 상왕십리 | F18: 상왕십리 | G18: 상왕십리역 | H18: FALSE
A19: 2 | B19: main | C19: 8 | D19: 왕십리_L2 | E19: 왕십리 | F19: 왕십리 | G19: 왕십리역 | H19: FALSE
A20: 2 | B20: main | C20: 9 | D20: 한양대_L2 | E20: 한양대 | F20: 한양대 | G20: 한양대역 | H20: FALSE
A21: 2 | B21: main | C21: 10 | D21: 뚝섬_L2 | E21: 뚝섬 | F21: 뚝섬 | G21: 뚝섬역 | H21: FALSE
A22: 2 | B22: main | C22: 11 | D22: 성수_L2 | E22: 성수 | F22: 성수 | G22: 성수역 | H22: FALSE
A23: 2 | B23: main | C23: 12 | D23: 건대입구_L2 | E23: 건대입구 | F23: 건대입구 | G23: 건대입구역 | H23: FALSE
A24: 2 | B24: main | C24: 13 | D24: 구의_L2 | E24: 구의 | F24: 구의 | G24: 구의역 | H24: FALSE
A25: 2 | B25: main | C25: 14 | D25: 강변_L2 | E25: 강변 | F25: 강변 | G25: 강변역 | H25: FALSE
A26: 2 | B26: main | C26: 15 | D26: 잠실나루_L2 | E26: 잠실나루 | F26: 잠실나루 | G26: 잠실나루역 | H26: FALSE
A27: 2 | B27: main | C27: 16 | D27: 잠실_L2 | E27: 잠실 | F27: 잠실 | G27: 잠실역 | H27: FALSE
A28: 2 | B28: main | C28: 17 | D28: 잠실새내_L2 | E28: 잠실새내 | F28: 잠실새내 | G28: 잠실새내역 | H28: FALSE
... A72: 3 | B72: main | C72: 8 | D72: 독립문_L3 | E72: 독립문 | F72: 독립문 | G72: 독립문역 | H72: FALSE
A73: 3 | B73: main | C73: 9 | D73: 경복궁_L3 | E73: 경복궁 | F73: 경복궁 | G73: 경복궁역 | H73: FALSE | I73: 경복궁(정부서울청사)
A74: 3 | B74: main | C74: 10 | D74: 안국_L3 | E74: 안국 | F74: 안국 | G74: 안국역 | H74: FALSE
A75: 3 | B75: main | C75: 11 | D75: 종로3가_L3 | E75: 종로3가 | F75: 종로3가 | G75: 종로3가역 | H75: FALSE
A76: 3 | B76: main | C76: 12 | D76: 을지로3가_L3 | E76: 을지로3가 | F76: 을지로3가 | G76: 을지로3가역 | H76: FALSE
A77: 3 | B77: main | C77: 13 | D77: 충무로_L3 | E77: 충무로 | F77: 충무로 | G77: 충무로역 | H77: FALSE
A78: 3 | B78: main | C78: 14 | D78: 동대입구_L3 | E78: 동대입구 | F78: 동대입구 | G78: 동대입구역 | H78: FALSE
A79: 3 | B79: main | C79: 15 | D79: 약수_L3 | E79: 약수 | F79: 약수 | G79: 약수역 | H79: FALSE
A80: 3 | B80: main | C80: 16 | D80: 금호_L3 | E80: 금호 | F80: 금호 | G80: 금호역 | H80: FALSE
A81: 3 | B81: main | C81: 17 | D81: 옥수_L3 | E81: 옥수 | F81: 옥수 | G81: 옥수역 | H81: FALSE
A82: 3 | B82: main | C82: 18 | D82: 압구정_L3 | E82: 압구정 | F82: 압구정 | G82: 압구정역 | H82: FALSE
A83: 3 | B83: main | C83: 19 | D83: 신사_L3 | E83: 신사 | F83: 신사 | G83: 신사역 | H83: FALSE
...

Sheet Transfer_Links
A1: station_key | B1: station_name | C1: from_line_id | D1: to_line_id | E1: from_visual_node_id | F1: to_visual_node_id | G1: transfer_style | H1: connector_visible | I1: connector_color | J1: memo
A2: 시청 | B2: 시청 | C2: 1 | D2: 2 | E2: 시청_L1 | F2: 시청_L2 | G2: connector | H2: TRUE | I2: #9CA3AF | J2: 지도 렌더링용 환승 연결선; 실제 환승 시간/거리 평가는 별도 환승 데이터 사용
A3: 신설동 | B3: 신설동 | C3: 1 | D3: 2 | E3: 신설동_L1 | F3: 신설동_L2 | G3: connector | H3: TRUE | I3: #9CA3AF | J3: 지도 렌더링용 환승 연결선; 실제 환승 시간/거리 평가는 별도 환승 데이터 사용
A4: 종로3가 | B4: 종로3가 | C4: 1 | D4: 3 | E4: 종로3가_L1 | F4: 종로3가_L3 | G4: connector | H4: TRUE | I4: #9CA3AF | J4: 지도 렌더링용 환승 연결선; 실제 환승 시간/거리 평가는 별도 환승 데이터 사용
A5: 동대문 | B5: 동대문 | C5: 1 | D5: 4 | E5: 동대문_L1 | F5: 동대문_L4 | G5: connector | H5: TRUE | I5: #9CA3AF | J5: 지도 렌더링용 환승 연결선; 실제 환승 시간/거리 평가는 별도 환승 데이터 사용
A6: 서울역 | B6: 서울역 | C6: 1 | D6: 4 | E6: 서울역_L1 | F6: 서울역_L4 | G6: connector | H6: TRUE | I6: #9CA3AF | J6: 지도 렌더링용 환승 연결선; 실제 환승 시간/거리 평가는 별도 환승 데이터 사용
A7: 종로3가 | B7: 종로3가 | C7: 1 | D7: 5 | E7: 종로3가_L1 | F7: 종로3가_L5 | G7: connector | H7: TRUE | I7: #9CA3AF | J7: 지도 렌더링용 환승 연결선; 실제 환승 시간/거리 평가는 별도 환승 데이터 사용
A8: 동묘앞 | B8: 동묘앞 | C8: 1 | D8: 6 | E8: 동묘앞_L1 | F8: 동묘앞_L6 | G8: connector | H8: TRUE | I8: #9CA3AF | J8: 지도 렌더링용 환승 연결선; 실제 환승 시간/거리 평가는 별도 환승 데이터 사용
A9: 교대 | B9: 교대 | C9: 2 | D9: 3 | E9: 교대_L2 | F9: 교대_L3 | G9: connector | H9: TRUE | I9: #9CA3AF | J9: 지도 렌더링용 환승 연결선; 실제 환승 시간/거리 평가는 별도 환승 데이터 사용
A10: 을지로3가 | B10: 을지로3가 | C10: 2 | D10: 3 | E10: 을지로3가_L2 | F10: 을지로3가_L3 | G10: connector | H10: TRUE | I10: #9CA3AF | J10: 지도 렌더링용 환승 연결선; 실제 환승 시간/거리 평가는 별도 환승 데이터 사용
A11: 동대문역사문화공원 | B11: 동대문역사문화공원 | C11: 2 | D11: 4 | E11: 동대문역사문화공원_L2 | F11: 동대문역사문화공원_L4 | G11: connector | H11: TRUE | I11: #9CA3AF | J11: 지도 렌더링용 환승 연결선; 실제 환승 시간/거리 평가는 별도 환승 데이터 사용
A12: 사당 | B12: 사당 | C12: 2 | D12: 4 | E12: 사당_L2 | F12: 사당_L4 | G12: connector | H12: TRUE | I12: #9CA3AF | J12: 지도 렌더링용 환승 연결선; 실제 환승 시간/거리 평가는 별도 환승 데이터 사용
A13: 까치산 | B13: 까치산 | C13: 2 | D13: 5 | E13: 까치산_L2 | F13: 까치산_L5 | G13: connector | H13: TRUE | I13: #9CA3AF | J13: 지도 렌더링용 환승 연결선; 실제 환승 시간/거리 평가는 별도 환승 데이터 사용
... A49: 석촌 | B49: 석촌 | C49: 8 | D49: 9 | E49: 석촌_L8 | F49: 석촌_L9 | G49: connector | H49: TRUE | I49: #9CA3AF | J49: 지도 렌더링용 환승 연결선

Sheet Station_Click_Areas
A1: mark_status | B1: station_key | C1: station_name | D1: display_name | E1: available_lines | F1: click_x_px | G1: click_y_px | H1: click_x_pct | I1: click_y_pct | J1: click_radius_px | K1: click_shape | L1: source_method | M1: manual_override_note | N1: click_dx | O1: click_dy
A2: 완료 | B2: 서울역 | C2: 서울역 | D2: 서울역 | E2: 1,4 | F2: =ROUND(AVERAGEIF(Station_Visual_Nodes!$D$2:$D$2000,$B2,Station_Visual_Nodes!$I$2:$I$2000)+N2,0) | G2: =ROUND(AVERAGEIF(Station_Visual_Nodes!$D$2:$D$2000,$B2,Station_Visual_Nodes!$J$2:$J$2000)+O2,0) | H2: =F2/5120*100 | I2: =G2/2880*100 | J2: 42 | K2: circle | L2: auto_from_visual_nodes_avg | N2: 0 | O2: 0
A3: 완료 | B3: 시청 | C3: 시청 | D3: 시청역 | E3: 1,2 | F3: =ROUND(AVERAGEIF(Station_Visual_Nodes!$D$2:$D$2000,$B3,Station_Visual_Nodes!$I$2:$I$2000)+N3,0) | G3: =ROUND(AVERAGEIF(Station_Visual_Nodes!$D$2:$D$2000,$B3,Station_Visual_Nodes!$J$2:$J$2000)+O3,0) | H3: =F3/5120*100 | I3: =G3/2880*100 | J3: 42 | K3: circle | L3: auto_from_visual_nodes_avg | N3: 0 | O3: 0
A4: 완료 | B4: 종각 | C4: 종각 | D4: 종각역 | E4: 1 | F4: =ROUND(AVERAGEIF(Station_Visual_Nodes!$D$2:$D$2000,$B4,Station_Visual_Nodes!$I$2:$I$2000)+N4,0) | G4: =ROUND(AVERAGEIF(Station_Visual_Nodes!$D$2:$D$2000,$B4,Station_Visual_Nodes!$J$2:$J$2000)+O4,0) | H4: =F4/5120*100 | I4: =G4/2880*100 | J4: 24 | K4: circle | L4: auto_from_visual_nodes_avg | N4: 0 | O4: 0
A5: 완료 | B5: 종로3가 | C5: 종로3가 | D5: 종로3가역 | E5: 1,3,5 | F5: =ROUND(AVERAGEIF(Station_Visual_Nodes!$D$2:$D$2000,$B5,Station_Visual_Nodes!$I$2:$I$2000)+N5,0) | G5: =ROUND(AVERAGEIF(Station_Visual_Nodes!$D$2:$D$2000,$B5,Station_Visual_Nodes!$J$2:$J$2000)+O5,0) | H5: =F5/5120*100 | I5: =G5/2880*100 | J5: 52 | K5: circle | L5: auto_from_visual_nodes_avg | N5: 0 | O5: 0
A6: 완료 | B6: 종로5가 | C6: 종로5가 | D6: 종로5가역 | E6: 1 | F6: 2206 | G6: 980 | H6: =F6/5120*100 | I6: =G6/2880*100 | J6: 24 | K6: circle | L6: auto_from_visual_nodes_avg | N6: 0 | O6: 0
A7: 완료 | B7: 동대문 | C7: 동대문 | D7: 동대문역 | E7: 1,4 | F7: =ROUND(AVERAGEIF(Station_Visual_Nodes!$D$2:$D$2000,$B7,Station_Visual_Nodes!$I$2:$I$2000)+N7,0) | G7: =ROUND(AVERAGEIF(Station_Visual_Nodes!$D$2:$D$2000,$B7,Station_Visual_Nodes!$J$2:$J$2000)+O7,0) | H7: =F7/5120*100 | I7: =G7/2880*100 | J7: 42 | K7: circle | L7: auto_from_visual_nodes_avg | N7: 0 | O7: 0
A8: 완료 | B8: 동묘앞 | C8: 동묘앞 | D8: 동묘앞역 | E8: 1,6 | F8: =ROUND(AVERAGEIF(Station_Visual_Nodes!$D$2:$D$2000,$B8,Station_Visual_Nodes!$I$2:$I$2000)+N8,0) | G8: =ROUND(AVERAGEIF(Station_Visual_Nodes!$D$2:$D$2000,$B8,Station_Visual_Nodes!$J$2:$J$2000)+O8,0) | H8: =F8/5120*100 | I8: =G8/2880*100 | J8: 42 | K8: circle | L8: auto_from_visual_nodes_avg | N8: 0 | O8: 0
A9: 완료 | B9: 신설동 | C9: 신설동 | D9: 신설동역 | E9: 1,2 | F9: =ROUND(AVERAGEIF(Station_Visual_Nodes!$D$2:$D$2000,$B9,Station_Visual_Nodes!$I$2:$I$2000)+N9,0) | G9: =ROUND(AVERAGEIF(Station_Visual_Nodes!$D$2:$D$2000,$B9,Station_Visual_Nodes!$J$2:$J$2000)+O9,0) | H9: =F9/5120*100 | I9: =G9/2880*100 | J9: 42 | K9: circle | L9: auto_from_visual_nodes_avg | N9: 0 | O9: 0
A10: 완료 | B10: 제기동 | C10: 제기동 | D10: 제기동역 | E10: 1 | F10: =ROUND(AVERAGEIF(Station_Visual_Nodes!$D$2:$D$2000,$B10,Station_Visual_Nodes!$I$2:$I$2000)+N10,0) | G10: =ROUND(AVERAGEIF(Station_Visual_Nodes!$D$2:$D$2000,$B10,Station_Visual_Nodes!$J$2:$J$2000)+O10,0) | H10: =F10/5120*100 | I10: =G10/2880*100 | J10: 24 | K10: circle | L10: auto_from_visual_nodes_avg | N10: 0 | O10: 0
A11: 완료 | B11: 청량리 | C11: 청량리 | D11: 청량리역 | E11: 1 | F11: =ROUND(AVERAGEIF(Station_Visual_Nodes!$D$2:$D$2000,$B11,Station_Visual_Nodes!$I$2:$I$2000)+N11,0) | G11: =ROUND(AVERAGEIF(Station_Visual_Nodes!$D$2:$D$2000,$B11,Station_Visual_Nodes!$J$2:$J$2000)+O11,0) | H11: =F11/5120*100 | I11: =G11/2880*100 | J11: 24 | K11: circle | L11: auto_from_visual_nodes_avg | N11: 0 | O11: 0
A12: 완료 | B12: 을지로입구 | C12: 을지로입구 | D12: 을지로입구역 | E12: 2 | F12: =ROUND(AVERAGEIF(Station_Visual_Nodes!$D$2:$D$2000,$B12,Station_Visual_Nodes!$I$2:$I$2000)+N12,0) | G12: =ROUND(AVERAGEIF(Station_Visual_Nodes!$D$2:$D$2000,$B12,Station_Visual_Nodes!$J$2:$J$2000)+O12,0) | H12: =F12/5120*100 | I12: =G12/2880*100 | J12: 24 | K12: circle | L12: auto_from_visual_nodes_avg | N12: 0 | O12: 0
A13: 완료 | B13: 을지로3가 | C13: 을지로3가 | D13: 을지로3가역 | E13: 2,3 | F13: =ROUND(AVERAGEIF(Station_Visual_Nodes!$D$2:$D$2000,$B13,Station_Visual_Nodes!$I$2:$I$2000)+N13,0) | G13: =ROUND(AVERAGEIF(Station_Visual_Nodes!$D$2:$D$2000,$B13,Station_Visual_Nodes!$J$2:$J$2000)+O13,0) | H13: =F13/5120*100 | I13: =G13/2880*100 | J13: 42 | K13: circle | L13: auto_from_visual_nodes_avg | N13: 0 | O13: 0
A14: 완료 | B14: 을지로4가 | C14: 을지로4가 | D14: 을지로4가역 | E14: 2,5 | F14: =ROUND(AVERAGEIF(Station_Visual_Nodes!$D$2:$D$2000,$B14,Station_Visual_Nodes!$I$2:$I$2000)+N14,0) | G14: =ROUND(AVERAGEIF(Station_Visual_Nodes!$D$2:$D$2000,$B14,Station_Visual_Nodes!$J$2:$J$2000)+O14,0) | H14: =F14/5120*100 | I14: =G14/2880*100 | J14: 42 | K14: circle | L14: auto_from_visual_nodes_avg | N14: 0 | O14: 0
A15: 완료 | B15: 동대문역사문화공원 | C15: 동대문역사문화공원 | D15: 동대문역사문화공원역 | E15: 2,4,5 | F15: =ROUND(AVERAGEIF(Station_Visual_Nodes!$D$2:$D$2000,$B15,Station_Visual_Nodes!$I$2:$I$2000)+N15,0) | G15: =ROUND(AVERAGEIF(Station_Visual_Nodes!$D$2:$D$2000,$B15,Station_Visual_Nodes!$J$2:$J$2000)+O15,0) | H15: =F15/5120*100 | I15: =G15/2880*100 | J15: 52 | K15: circle | L15: auto_from_visual_nodes_avg | N15: 0 | O15: 0
A16: 완료 | B16: 신당 | C16: 신당 | D16: 신당역 | E16: 2,6 | F16: =ROUND(AVERAGEIF(Station_Visual_Nodes!$D$2:$D$2000,$B16,Station_Visual_Nodes!$I$2:$I$2000)+N16,0) | G16: =ROUND(AVERAGEIF(Station_Visual_Nodes!$D$2:$D$2000,$B16,Station_Visual_Nodes!$J$2:$J$2000)+O16,0) | H16: =F16/5120*100 | I16: =G16/2880*100 | J16: 42 | K16: circle | L16: auto_from_visual_nodes_avg | N16: 0 | O16: 0
A17: 완료 | B17: 상왕십리 | C17: 상왕십리 | D17: 상왕십리역 | E17: 2 | F17: =ROUND(AVERAGEIF(Station_Visual_Nodes!$D$2:$D$2000,$B17,Station_Visual_Nodes!$I$2:$I$2000)+N17,0) | G17: =ROUND(AVERAGEIF(Station_Visual_Nodes!$D$2:$D$2000,$B17,Station_Visual_Nodes!$J$2:$J$2000)+O17,0) | H17: =F17/5120*100 | I17: =G17/2880*100 | J17: 24 | K17: circle | L17: auto_from_visual_nodes_avg | N17: 0 | O17: 0
A18: 완료 | B18: 왕십리 | C18: 왕십리 | D18: 왕십리역 | E18: 2,5 | F18: =ROUND(AVERAGEIF(Station_Visual_Nodes!$D$2:$D$2000,$B18,Station_Visual_Nodes!$I$2:$I$2000)+N18,0) | G18: =ROUND(AVERAGEIF(Station_Visual_Nodes!$D$2:$D$2000,$B18,Station_Visual_Nodes!$J$2:$J$2000)+O18,0) | H18: =F18/5120*100 | I18: =G18/2880*100 | J18: 42 | K18: circle | L18: auto_from_visual_nodes_avg | N18: 0 | O18: 0
A19: 완료 | B19: 한양대 | C19: 한양대 | D19: 한양대역 | E19: 2 | F19: 2816 | G19: 1194 | H19: =F19/5120*100 | I19: =G19/2880*100 | J19: 24 | K19: circle | L19: auto_from_visual_nodes_avg | N19: 0 | O19: 0
A20: 완료 | B20: 뚝섬 | C20: 뚝섬 | D20: 뚝섬역 | E20: 2 | F20: 2896 | G20: 1244 | H20: =F20/5120*100 | I20: =G20/2880*100 | J20: 24 | K20: circle | L20: auto_from_visual_nodes_avg | N20: 0 | O20: 0
A21: 완료 | B21: 성수 | C21: 성수 | D21: 성수역 | E21: 2 | F21: =ROUND(AVERAGEIF(Station_Visual_Nodes!$D$2:$D$2000,$B21,Station_Visual_Nodes!$I$2:$I$2000)+N21,0) | G21: =ROUND(AVERAGEIF(Station_Visual_Nodes!$D$2:$D$2000,$B21,Station_Visual_Nodes!$J$2:$J$2000)+O21,0) | H21: =F21/5120*100 | I21: =G21/2880*100 | J21: 24 | K21: circle | L21: auto_from_visual_nodes_avg | N21: 0 | O21: 0
A22: 완료 | B22: 건대입구 | C22: 건대입구 | D22: 건대입구역 | E22: 2,7 | F22: =ROUND(AVERAGEIF(Station_Visual_Nodes!$D$2:$D$2000,$B22,Station_Visual_Nodes!$I$2:$I$2000)+N22,0) | G22: =ROUND(AVERAGEIF(Station_Visual_Nodes!$D$2:$D$2000,$B22,Station_Visual_Nodes!$J$2:$J$2000)+O22,0) | H22: =F22/5120*100 | I22: =G22/2880*100 | J22: 42 | K22: circle | L22: auto_from_visual_nodes_avg | N22: 0 | O22: 0
A23: 완료 | B23: 구의 | C23: 구의 | D23: 구의역 | E23: 2 | F23: =ROUND(AVERAGEIF(Station_Visual_Nodes!$D$2:$D$2000,$B23,Station_Visual_Nodes!$I$2:$I$2000)+N23,0) | G23: =ROUND(AVERAGEIF(Station_Visual_Nodes!$D$2:$D$2000,$B23,Station_Visual_Nodes!$J$2:$J$2000)+O23,0) | H23: =F23/5120*100 | I23: =G23/2880*100 | J23: 24 | K23: circle | L23: auto_from_visual_nodes_avg | N23: 0 | O23: 0
A24: 완료 | B24: 강변 | C24: 강변 | D24: 강변역 | E24: 2 | F24: =ROUND(AVERAGEIF(Station_Visual_Nodes!$D$2:$D$2000,$B24,Station_Visual_Nodes!$I$2:$I$2000)+N24,0) | G24: =ROUND(AVERAGEIF(Station_Visual_Nodes!$D$2:$D$2000,$B24,Station_Visual_Nodes!$J$2:$J$2000)+O24,0) | H24: =F24/5120*100 | I24: =G24/2880*100 | J24: 24 | K24: circle | L24: auto_from_visual_nodes_avg | N24: 0 | O24: 0
A25: 완료 | B25: 잠실나루 | C25: 잠실나루 | D25: 잠실나루역 | E25: 2 | F25: =ROUND(AVERAGEIF(Station_Visual_Nodes!$D$2:$D$2000,$B25,Station_Visual_Nodes!$I$2:$I$2000)+N25,0) | G25: =ROUND(AVERAGEIF(Station_Visual_Nodes!$D$2:$D$2000,$B25,Station_Visual_Nodes!$J$2:$J$2000)+O25,0) | H25: =F25/5120*100 | I25: =G25/2880*100 | J25: 24 | K25: circle | L25: auto_from_visual_nodes_avg | N25: 0 | O25: 0
A26: 완료 | B26: 잠실 | C26: 잠실 | D26: 잠실역 | E26: 2,8 | F26: =ROUND(AVERAGEIF(Station_Visual_Nodes!$D$2:$D$2000,$B26,Station_Visual_Nodes!$I$2:$I$2000)+N26,0) | G26: =ROUND(AVERAGEIF(Station_Visual_Nodes!$D$2:$D$2000,$B26,Station_Visual_Nodes!$J$2:$J$2000)+O26,0) | H26: =F26/5120*100 | I26: =G26/2880*100 | J26: 42 | K26: circle | L26: auto_from_visual_nodes_avg | N26: 0 | O26: 0
A27: 완료 | B27: 잠실새내 | C27: 잠실새내 | D27: 잠실새내역 | E27: 2 | F27: =ROUND(AVERAGEIF(Station_Visual_Nodes!$D$2:$D$2000,$B27,Station_Visual_Nodes!$I$2:$I$2000)+N27,0) | G27: =ROUND(AVERAGEIF(Station_Visual_Nodes!$D$2:$D$2000,$B27,Station_Visual_Nodes!$J$2:$J$2000)+O27,0) | H27: =F27/5120*100 | I27: =G27/2880*100 | J27: 24 | K27: circle | L27: auto_from_visual_nodes_avg | N27: 0 | O27: 0
A28: 완료 | B28: 종합운동장 | C28: 종합운동장 | D28: 종합운동장역 | E28: 2,9 | F28: =ROUND(AVERAGEIF(Station_Visual_Nodes!$D$2:$D$2000,$B28,Station_Visual_Nodes!$I$2:$I$2000)+N28,0) | G28: =ROUND(AVERAGEIF(Station_Visual_Nodes!$D$2:$D$2000,$B28,Station_Visual_Nodes!$J$2:$J$2000)+O28,0) | H28: =F28/5120*100 | I28: =G28/2880*100 | J28: 24 | K28: circle | L28: auto_from_visual_nodes_avg | N28: 0 | O28: 0
A29: 완료 | B29: 삼성 | C29: 삼성 | D29: 삼성역 | E29: 2 | F29: =ROUND(AVERAGEIF(Station_Visual_Nodes!$D$2:$D$2000,$B29,Station_Visual_Nodes!$I$2:$I$2000)+N29,0) | G29: =ROUND(AVERAGEIF(Station_Visual_Nodes!$D$2:$D$2000,$B29,Station_Visual_Nodes!$J$2:$J$2000)+O29,0) | H29: =F29/5120*100 | I29: =G29/2880*100 | J29: 24 | K29: circle | L29: auto_from_visual_nodes_avg | N29: 0 | O29: 0
A30: 완료 | B30: 선릉 | C30: 선릉 | D30: 선릉역 | E30: 2 | F30: =ROUND(AVERAGEIF(Station_Visual_Nodes!$D$2:$D$2000,$B30,Station_Visual_Nodes!$I$2:$I$2000)+N30,0) | G30: =ROUND(AVERAGEIF(Station_Visual_Nodes!$D$2:$D$2000,$B30,Station_Visual_Nodes!$J$2:$J$2000)+O30,0) | H30: =F30/5120*100 | I30: =G30/2880*100 | J30: 24 | K30: circle | L30: auto_from_visual_nodes_avg | N30: 0 | O30: 0
A31: 완료 | B31: 역삼 | C31: 역삼 | D31: 역삼역 | E31: 2 | F31: =ROUND(AVERAGEIF(Station_Visual_Nodes!$D$2:$D$2000,$B31,Station_Visual_Nodes!$I$2:$I$2000)+N31,0) | G31: =ROUND(AVERAGEIF(Station_Visual_Nodes!$D$2:$D$2000,$B31,Station_Visual_Nodes!$J$2:$J$2000)+O31,0) | H31: =F31/5120*100 | I31: =G31/2880*100 | J31: 24 | K31: circle | L31: auto_from_visual_nodes_avg | N31: 0 | O31: 0
A32: 완료 | B32: 강남 | C32: 강남 | D32: 강남역 | E32: 2 | F32: =ROUND(AVERAGEIF(Station_Visual_Nodes!$D$2:$D$2000,$B32,Station_Visual_Nodes!$I$2:$I$2000)+N32,0) | G32: =ROUND(AVERAGEIF(Station_Visual_Nodes!$D$2:$D$2000,$B32,Station_Visual_Nodes!$J$2:$J$2000)+O32,0) | H32: =F32/5120*100 | I32: =G32/2880*100 | J32: 24 | K32: circle | L32: auto_from_visual_nodes_avg | N32: 0 | O32: 0
... A112: 완료 | B112: 남태령 | C112: 남태령 | D112: 남태령역 | E112: 4 | F112: =ROUND(AVERAGEIF(Station_Visual_Nodes!$D$2:$D$2000,$B112,Station_Visual_Nodes!$I$2:$I$2000)+N112,0) | G112: =ROUND(AVERAGEIF(Station_Visual_Nodes!$D$2:$D$2000,$B112,Station_Visual_Nodes!$J$2:$J$2000)+O112,0) | H112: =F112/5120*100 | I112: =G112/2880*100 | J112: 24 | K112: circle | L112: auto_from_visual_nodes_avg | N112: 0 | O112: 0
A113: 완료 | B113: 방화 | C113: 방화 | D113: 방화역 | E113: 5 | F113: 788 | G113: 800 | H113: =F113/5120*100 | I113: =G113/2880*100 | J113: 24 | K113: circle | L113: auto_from_visual_nodes_avg | N113: 0 | O113: 0
A114: 완료 | B114: 개화산 | C114: 개화산 | D114: 개화산역 | E114: 5 | F114: 788 | G114: 884 | H114: =F114/5120*100 | I114: =G114/2880*100 | J114: 24 | K114: circle | L114: auto_from_visual_nodes_avg | N114: 0 | O114: 0
A115: 완료 | B115: 김포공항 | C115: 김포공항 | D115: 김포공항역 | E115: 5,9 | F115: 788 | G115: 960 | H115: =F115/5120*100 | I115: =G115/2880*100 | J115: 24 | K115: circle | L115: auto_from_visual_nodes_avg | N115: 0 | O115: 0
A116: 완료 | B116: 송정 | C116: 송정 | D116: 송정역 | E116: 5 | F116: =ROUND(AVERAGEIF(Station_Visual_Nodes!$D$2:$D$2000,$B116,Station_Visual_Nodes!$I$2:$I$2000)+N116,0) | G116: =ROUND(AVERAGEIF(Station_Visual_Nodes!$D$2:$D$2000,$B116,Station_Visual_Nodes!$J$2:$J$2000)+O116,0) | H116: =F116/5120*100 | I116: =G116/2880*100 | J116: 24 | K116: circle | L116: auto_from_visual_nodes_avg | N116: 0 | O116: 0
A117: 완료 | B117: 마곡 | C117: 마곡 | D117: 마곡역 | E117: 5 | F117: =ROUND(AVERAGEIF(Station_Visual_Nodes!$D$2:$D$2000,$B117,Station_Visual_Nodes!$I$2:$I$2000)+N117,0) | G117: =ROUND(AVERAGEIF(Station_Visual_Nodes!$D$2:$D$2000,$B117,Station_Visual_Nodes!$J$2:$J$2000)+O117,0) | H117: =F117/5120*100 | I117: =G117/2880*100 | J117: 24 | K117: circle | L117: auto_from_visual_nodes_avg | N117: 0 | O117: 0
A118: 완료 | B118: 발산 | C118: 발산 | D118: 발산역 | E118: 5 | F118: =ROUND(AVERAGEIF(Station_Visual_Nodes!$D$2:$D$2000,$B118,Station_Visual_Nodes!$I$2:$I$2000)+N118,0) | G118: =ROUND(AVERAGEIF(Station_Visual_Nodes!$D$2:$D$2000,$B118,Station_Visual_Nodes!$J$2:$J$2000)+O118,0) | H118: =F118/5120*100 | I118: =G118/2880*100 | J118: 24 | K118: circle | L118: auto_from_visual_nodes_avg | N118: 0 | O118: 0
A119: 완료 | B119: 우장산 | C119: 우장산 | D119: 우장산역 | E119: 5 | F119: =ROUND(AVERAGEIF(Station_Visual_Nodes!$D$2:$D$2000,$B119,Station_Visual_Nodes!$I$2:$I$2000)+N119,0) | G119: =ROUND(AVERAGEIF(Station_Visual_Nodes!$D$2:$D$2000,$B119,Station_Visual_Nodes!$J$2:$J$2000)+O119,0) | H119: =F119/5120*100 | I119: =G119/2880*100 | J119: 24 | K119: circle | L119: auto_from_visual_nodes_avg | N119: 0 | O119: 0
...

Sheet Station_Labels
A1: mark_status | B1: station_key | C1: station_name | D1: display_name | E1: available_lines | F1: label_x_px | G1: label_y_px | H1: label_x_pct | I1: label_y_pct | J1: label_size_px | K1: label_weight | L1: label_anchor | M1: label_rotation | N1: source_method | O1: memo | P1: label_dx | Q1: label_dy
A2: 완료 | B2: 서울역 | C2: 서울역 | D2: 서울역 | E2: 1,4 | F2: =ROUND(AVERAGEIF(Station_Visual_Nodes!$D$2:$D$2000,$B2,Station_Visual_Nodes!$I$2:$I$2000)+P2,0) | G2: =ROUND(AVERAGEIF(Station_Visual_Nodes!$D$2:$D$2000,$B2,Station_Visual_Nodes!$J$2:$J$2000)+Q2,0) | H2: =F2/5120*100 | I2: =G2/2880*100 | J2: 12 | K2: bold | L2: center | M2: 0 | N2: default_from_click_area | P2: 0 | Q2: 0
A3: 완료 | B3: 시청 | C3: 시청 | D3: 시청역 | E3: 1,2 | F3: =ROUND(AVERAGEIF(Station_Visual_Nodes!$D$2:$D$2000,$B3,Station_Visual_Nodes!$I$2:$I$2000)+P3,0) | G3: =ROUND(AVERAGEIF(Station_Visual_Nodes!$D$2:$D$2000,$B3,Station_Visual_Nodes!$J$2:$J$2000)+Q3,0) | H3: =F3/5120*100 | I3: =G3/2880*100 | J3: 12 | K3: bold | L3: center | M3: 0 | N3: default_from_click_area | P3: 0 | Q3: 0
A4: 완료 | B4: 종각 | C4: 종각 | D4: 종각역 | E4: 1 | F4: =ROUND(AVERAGEIF(Station_Visual_Nodes!$D$2:$D$2000,$B4,Station_Visual_Nodes!$I$2:$I$2000)+P4,0) | G4: =ROUND(AVERAGEIF(Station_Visual_Nodes!$D$2:$D$2000,$B4,Station_Visual_Nodes!$J$2:$J$2000)+Q4,0) | H4: =F4/5120*100 | I4: =G4/2880*100 | J4: 10.5 | K4: normal | L4: center | M4: 0 | N4: default_from_click_area | P4: 0 | Q4: 0
A5: 완료 | B5: 종로3가 | C5: 종로3가 | D5: 종로3가역 | E5: 1,3,5 | F5: =ROUND(AVERAGEIF(Station_Visual_Nodes!$D$2:$D$2000,$B5,Station_Visual_Nodes!$I$2:$I$2000)+P5,0) | G5: =ROUND(AVERAGEIF(Station_Visual_Nodes!$D$2:$D$2000,$B5,Station_Visual_Nodes!$J$2:$J$2000)+Q5,0) | H5: =F5/5120*100 | I5: =G5/2880*100 | J5: 13 | K5: bold | L5: center | M5: 0 | N5: default_from_click_area | P5: 0 | Q5: 0
A6: 완료 | B6: 종로5가 | C6: 종로5가 | D6: 종로5가역 | E6: 1 | F6: 2206 | G6: =ROUND(AVERAGEIF(Station_Visual_Nodes!$D$2:$D$2000,$B6,Station_Visual_Nodes!$J$2:$J$2000)+Q6,0) | H6: =F6/5120*100 | I6: =G6/2880*100 | J6: 10.5 | K6: normal | L6: center | M6: 0 | N6: default_from_click_area | P6: 0 | Q6: 0
A7: 완료 | B7: 동대문 | C7: 동대문 | D7: 동대문역 | E7: 1,4 | F7: =ROUND(AVERAGEIF(Station_Visual_Nodes!$D$2:$D$2000,$B7,Station_Visual_Nodes!$I$2:$I$2000)+P7,0) | G7: =ROUND(AVERAGEIF(Station_Visual_Nodes!$D$2:$D$2000,$B7,Station_Visual_Nodes!$J$2:$J$2000)+Q7,0) | H7: =F7/5120*100 | I7: =G7/2880*100 | J7: 12 | K7: bold | L7: center | M7: 0 | N7: default_from_click_area | P7: 0 | Q7: 0
A8: 완료 | B8: 동묘앞 | C8: 동묘앞 | D8: 동묘앞역 | E8: 1,6 | F8: =ROUND(AVERAGEIF(Station_Visual_Nodes!$D$2:$D$2000,$B8,Station_Visual_Nodes!$I$2:$I$2000)+P8,0) | G8: =ROUND(AVERAGEIF(Station_Visual_Nodes!$D$2:$D$2000,$B8,Station_Visual_Nodes!$J$2:$J$2000)+Q8,0) | H8: =F8/5120*100 | I8: =G8/2880*100 | J8: 12 | K8: bold | L8: center | M8: 0 | N8: default_from_click_area | P8: 0 | Q8: 0
A9: 완료 | B9: 신설동 | C9: 신설동 | D9: 신설동역 | E9: 1,2 | F9: =ROUND(AVERAGEIF(Station_Visual_Nodes!$D$2:$D$2000,$B9,Station_Visual_Nodes!$I$2:$I$2000)+P9,0) | G9: =ROUND(AVERAGEIF(Station_Visual_Nodes!$D$2:$D$2000,$B9,Station_Visual_Nodes!$J$2:$J$2000)+Q9,0) | H9: =F9/5120*100 | I9: =G9/2880*100 | J9: 12 | K9: bold | L9: center | M9: 0 | N9: default_from_click_area | P9: 0 | Q9: 0
A10: 완료 | B10: 제기동 | C10: 제기동 | D10: 제기동역 | E10: 1 | F10: =ROUND(AVERAGEIF(Station_Visual_Nodes!$D$2:$D$2000,$B10,Station_Visual_Nodes!$I$2:$I$2000)+P10,0) | G10: =ROUND(AVERAGEIF(Station_Visual_Nodes!$D$2:$D$2000,$B10,Station_Visual_Nodes!$J$2:$J$2000)+Q10,0) | H10: =F10/5120*100 | I10: =G10/2880*100 | J10: 10.5 | K10: normal | L10: center | M10: 0 | N10: default_from_click_area | P10: 0 | Q10: 0
A11: 완료 | B11: 청량리 | C11: 청량리 | D11: 청량리역 | E11: 1 | F11: =ROUND(AVERAGEIF(Station_Visual_Nodes!$D$2:$D$2000,$B11,Station_Visual_Nodes!$I$2:$I$2000)+P11,0) | G11: =ROUND(AVERAGEIF(Station_Visual_Nodes!$D$2:$D$2000,$B11,Station_Visual_Nodes!$J$2:$J$2000)+Q11,0) | H11: =F11/5120*100 | I11: =G11/2880*100 | J11: 10.5 | K11: normal | L11: center | M11: 0 | N11: default_from_click_area | P11: 0 | Q11: 0
A12: 완료 | B12: 을지로입구 | C12: 을지로입구 | D12: 을지로입구역 | E12: 2 | F12: =ROUND(AVERAGEIF(Station_Visual_Nodes!$D$2:$D$2000,$B12,Station_Visual_Nodes!$I$2:$I$2000)+P12,0) | G12: =ROUND(AVERAGEIF(Station_Visual_Nodes!$D$2:$D$2000,$B12,Station_Visual_Nodes!$J$2:$J$2000)+Q12,0) | H12: =F12/5120*100 | I12: =G12/2880*100 | J12: 10.5 | K12: normal | L12: center | M12: 0 | N12: default_from_click_area | O12: 역명 가로 -5 (5px 겹침 방지, D-068) | P12: -5 | Q12: 0
A13: 완료 | B13: 을지로3가 | C13: 을지로3가 | D13: 을지로3가역 | E13: 2,3 | F13: =ROUND(AVERAGEIF(Station_Visual_Nodes!$D$2:$D$2000,$B13,Station_Visual_Nodes!$I$2:$I$2000)+P13,0) | G13: =ROUND(AVERAGEIF(Station_Visual_Nodes!$D$2:$D$2000,$B13,Station_Visual_Nodes!$J$2:$J$2000)+Q13,0) | H13: =F13/5120*100 | I13: =G13/2880*100 | J13: 12 | K13: bold | L13: center | M13: 0 | N13: default_from_click_area | P13: 0 | Q13: 0
A14: 완료 | B14: 을지로4가 | C14: 을지로4가 | D14: 을지로4가역 | E14: 2,5 | F14: =ROUND(AVERAGEIF(Station_Visual_Nodes!$D$2:$D$2000,$B14,Station_Visual_Nodes!$I$2:$I$2000)+P14,0) | G14: =ROUND(AVERAGEIF(Station_Visual_Nodes!$D$2:$D$2000,$B14,Station_Visual_Nodes!$J$2:$J$2000)+Q14,0) | H14: =F14/5120*100 | I14: =G14/2880*100 | J14: 12 | K14: bold | L14: center | M14: 0 | N14: default_from_click_area | O14: 역명 가로 -10 (5px 겹침 방지, D-068) | P14: -10 | Q14: 0
A15: 완료 | B15: 동대문역사문화공원 | C15: 동대문역사문화공원 | D15: 동대문역사문화공원역 | E15: 2,4,5 | F15: =ROUND(AVERAGEIF(Station_Visual_Nodes!$D$2:$D$2000,$B15,Station_Visual_Nodes!$I$2:$I$2000)+P15,0) | G15: =ROUND(AVERAGEIF(Station_Visual_Nodes!$D$2:$D$2000,$B15,Station_Visual_Nodes!$J$2:$J$2000)+Q15,0) | H15: =F15/5120*100 | I15: =G15/2880*100 | J15: 13 | K15: bold | L15: center | M15: 0 | N15: default_from_click_area | O15: 역명 가로 +13 (5px 겹침 방지, D-068) | P15: 13 | Q15: 0
A16: 완료 | B16: 신당 | C16: 신당 | D16: 신당역 | E16: 2,6 | F16: =ROUND(AVERAGEIF(Station_Visual_Nodes!$D$2:$D$2000,$B16,Station_Visual_Nodes!$I$2:$I$2000)+P16,0) | G16: =ROUND(AVERAGEIF(Station_Visual_Nodes!$D$2:$D$2000,$B16,Station_Visual_Nodes!$J$2:$J$2000)+Q16,0) | H16: =F16/5120*100 | I16: =G16/2880*100 | J16: 12 | K16: bold | L16: center | M16: 0 | N16: default_from_click_area | P16: 0 | Q16: 0
A17: 완료 | B17: 상왕십리 | C17: 상왕십리 | D17: 상왕십리역 | E17: 2 | F17: =ROUND(AVERAGEIF(Station_Visual_Nodes!$D$2:$D$2000,$B17,Station_Visual_Nodes!$I$2:$I$2000)+P17,0) | G17: =ROUND(AVERAGEIF(Station_Visual_Nodes!$D$2:$D$2000,$B17,Station_Visual_Nodes!$J$2:$J$2000)+Q17,0) | H17: =F17/5120*100 | I17: =G17/2880*100 | J17: 10.5 | K17: normal | L17: center | M17: 0 | N17: default_from_click_area | P17: 0 | Q17: 0
A18: 완료 | B18: 왕십리 | C18: 왕십리 | D18: 왕십리역 | E18: 2,5 | F18: =ROUND(AVERAGEIF(Station_Visual_Nodes!$D$2:$D$2000,$B18,Station_Visual_Nodes!$I$2:$I$2000)+P18,0) | G18: =ROUND(AVERAGEIF(Station_Visual_Nodes!$D$2:$D$2000,$B18,Station_Visual_Nodes!$J$2:$J$2000)+Q18,0) | H18: =F18/5120*100 | I18: =G18/2880*100 | J18: 12 | K18: bold | L18: center | M18: 0 | N18: default_from_click_area | P18: 0 | Q18: 0
A19: 완료 | B19: 한양대 | C19: 한양대 | D19: 한양대역 | E19: 2 | F19: 2816 | G19: 1194 | H19: =F19/5120*100 | I19: =G19/2880*100 | J19: 10.5 | K19: normal | L19: center | M19: 0 | N19: default_from_click_area | P19: 0 | Q19: 0
A20: 완료 | B20: 뚝섬 | C20: 뚝섬 | D20: 뚝섬역 | E20: 2 | F20: 2896 | G20: 1244 | H20: =F20/5120*100 | I20: =G20/2880*100 | J20: 10.5 | K20: normal | L20: center | M20: 0 | N20: default_from_click_area | P20: 0 | Q20: 0
A21: 완료 | B21: 성수 | C21: 성수 | D21: 성수역 | E21: 2 | F21: =ROUND(AVERAGEIF(Station_Visual_Nodes!$D$2:$D$2000,$B21,Station_Visual_Nodes!$I$2:$I$2000)+P21,0) | G21: =ROUND(AVERAGEIF(Station_Visual_Nodes!$D$2:$D$2000,$B21,Station_Visual_Nodes!$J$2:$J$2000)+Q21,0) | H21: =F21/5120*100 | I21: =G21/2880*100 | J21: 10.5 | K21: normal | L21: center | M21: 0 | N21: default_from_click_area | P21: 0 | Q21: 0
A22: 완료 | B22: 건대입구 | C22: 건대입구 | D22: 건대입구역 | E22: 2,7 | F22: =ROUND(AVERAGEIF(Station_Visual_Nodes!$D$2:$D$2000,$B22,Station_Visual_Nodes!$I$2:$I$2000)+P22,0) | G22: =ROUND(AVERAGEIF(Station_Visual_Nodes!$D$2:$D$2000,$B22,Station_Visual_Nodes!$J$2:$J$2000)+Q22,0) | H22: =F22/5120*100 | I22: =G22/2880*100 | J22: 12 | K22: bold | L22: center | M22: 0 | N22: default_from_click_area | P22: 0 | Q22: 0
A23: 완료 | B23: 구의 | C23: 구의 | D23: 구의역 | E23: 2 | F23: =ROUND(AVERAGEIF(Station_Visual_Nodes!$D$2:$D$2000,$B23,Station_Visual_Nodes!$I$2:$I$2000)+P23,0) | G23: =ROUND(AVERAGEIF(Station_Visual_Nodes!$D$2:$D$2000,$B23,Station_Visual_Nodes!$J$2:$J$2000)+Q23,0) | H23: =F23/5120*100 | I23: =G23/2880*100 | J23: 10.5 | K23: normal | L23: center | M23: 0 | N23: default_from_click_area | P23: 0 | Q23: 0
A24: 완료 | B24: 강변 | C24: 강변 | D24: 강변역 | E24: 2 | F24: =ROUND(AVERAGEIF(Station_Visual_Nodes!$D$2:$D$2000,$B24,Station_Visual_Nodes!$I$2:$I$2000)+P24,0) | G24: =ROUND(AVERAGEIF(Station_Visual_Nodes!$D$2:$D$2000,$B24,Station_Visual_Nodes!$J$2:$J$2000)+Q24,0) | H24: =F24/5120*100 | I24: =G24/2880*100 | J24: 10.5 | K24: normal | L24: center | M24: 0 | N24: default_from_click_area | P24: 0 | Q24: 0
A25: 완료 | B25: 잠실나루 | C25: 잠실나루 | D25: 잠실나루역 | E25: 2 | F25: =ROUND(AVERAGEIF(Station_Visual_Nodes!$D$2:$D$2000,$B25,Station_Visual_Nodes!$I$2:$I$2000)+P25,0) | G25: =ROUND(AVERAGEIF(Station_Visual_Nodes!$D$2:$D$2000,$B25,Station_Visual_Nodes!$J$2:$J$2000)+Q25,0) | H25: =F25/5120*100 | I25: =G25/2880*100 | J25: 10.5 | K25: normal | L25: center | M25: 0 | N25: default_from_click_area | P25: 0 | Q25: 0
A26: 완료 | B26: 잠실 | C26: 잠실 | D26: 잠실역 | E26: 2,8 | F26: =ROUND(AVERAGEIF(Station_Visual_Nodes!$D$2:$D$2000,$B26,Station_Visual_Nodes!$I$2:$I$2000)+P26,0) | G26: =ROUND(AVERAGEIF(Station_Visual_Nodes!$D$2:$D$2000,$B26,Station_Visual_Nodes!$J$2:$J$2000)+Q26,0) | H26: =F26/5120*100 | I26: =G26/2880*100 | J26: 12 | K26: bold | L26: center | M26: 0 | N26: default_from_click_area | P26: 0 | Q26: 0
A27: 완료 | B27: 잠실새내 | C27: 잠실새내 | D27: 잠실새내역 | E27: 2 | F27: =ROUND(AVERAGEIF(Station_Visual_Nodes!$D$2:$D$2000,$B27,Station_Visual_Nodes!$I$2:$I$2000)+P27,0) | G27: =ROUND(AVERAGEIF(Station_Visual_Nodes!$D$2:$D$2000,$B27,Station_Visual_Nodes!$J$2:$J$2000)+Q27,0) | H27: =F27/5120*100 | I27: =G27/2880*100 | J27: 10.5 | K27: normal | L27: center | M27: 0 | N27: default_from_click_area | P27: 0 | Q27: 0
A28: 완료 | B28: 종합운동장 | C28: 종합운동장 | D28: 종합운동장역 | E28: 2,9 | F28: =ROUND(AVERAGEIF(Station_Visual_Nodes!$D$2:$D$2000,$B28,Station_Visual_Nodes!$I$2:$I$2000)+P28,0) | G28: =ROUND(AVERAGEIF(Station_Visual_Nodes!$D$2:$D$2000,$B28,Station_Visual_Nodes!$J$2:$J$2000)+Q28,0) | H28: =F28/5120*100 | I28: =G28/2880*100 | J28: 10.5 | K28: normal | L28: center | M28: 0 | N28: default_from_click_area | O28: 역명 가로 +2 (5px 겹침 방지, D-068) | P28: 2 | Q28: 0
A29: 완료 | B29: 삼성 | C29: 삼성 | D29: 삼성역 | E29: 2 | F29: =ROUND(AVERAGEIF(Station_Visual_Nodes!$D$2:$D$2000,$B29,Station_Visual_Nodes!$I$2:$I$2000)+P29,0) | G29: =ROUND(AVERAGEIF(Station_Visual_Nodes!$D$2:$D$2000,$B29,Station_Visual_Nodes!$J$2:$J$2000)+Q29,0) | H29: =F29/5120*100 | I29: =G29/2880*100 | J29: 10.5 | K29: normal | L29: center | M29: 0 | N29: default_from_click_area | P29: 0 | Q29: 0
A30: 완료 | B30: 선릉 | C30: 선릉 | D30: 선릉역 | E30: 2 | F30: =ROUND(AVERAGEIF(Station_Visual_Nodes!$D$2:$D$2000,$B30,Station_Visual_Nodes!$I$2:$I$2000)+P30,0) | G30: =ROUND(AVERAGEIF(Station_Visual_Nodes!$D$2:$D$2000,$B30,Station_Visual_Nodes!$J$2:$J$2000)+Q30,0) | H30: =F30/5120*100 | I30: =G30/2880*100 | J30: 10.5 | K30: normal | L30: center | M30: 0 | N30: default_from_click_area | P30: 0 | Q30: 0
A31: 완료 | B31: 역삼 | C31: 역삼 | D31: 역삼역 | E31: 2 | F31: =ROUND(AVERAGEIF(Station_Visual_Nodes!$D$2:$D$2000,$B31,Station_Visual_Nodes!$I$2:$I$2000)+P31,0) | G31: =ROUND(AVERAGEIF(Station_Visual_Nodes!$D$2:$D$2000,$B31,Station_Visual_Nodes!$J$2:$J$2000)+Q31,0) | H31: =F31/5120*100 | I31: =G31/2880*100 | J31: 10.5 | K31: normal | L31: center | M31: 0 | N31: default_from_click_area | P31: 0 | Q31: 0
A32: 완료 | B32: 강남 | C32: 강남 | D32: 강남역 | E32: 2 | F32: =ROUND(AVERAGEIF(Station_Visual_Nodes!$D$2:$D$2000,$B32,Station_Visual_Nodes!$I$2:$I$2000)+P32,0) | G32: =ROUND(AVERAGEIF(Station_Visual_Nodes!$D$2:$D$2000,$B32,Station_Visual_Nodes!$J$2:$J$2000)+Q32,0) | H32: =F32/5120*100 | I32: =G32/2880*100 | J32: 10.5 | K32: normal | L32: center | M32: 0 | N32: default_from_click_area | P32: 0 | Q32: 0
A33: 완료 | B33: 교대 | C33: 교대 | D33: 교대역 | E33: 2,3 | F33: =ROUND(AVERAGEIF(Station_Visual_Nodes!$D$2:$D$2000,$B33,Station_Visual_Nodes!$I$2:$I$2000)+P33,0) | G33: =ROUND(AVERAGEIF(Station_Visual_Nodes!$D$2:$D$2000,$B33,Station_Visual_Nodes!$J$2:$J$2000)+Q33,0) | H33: =F33/5120*100 | I33: =G33/2880*100 | J33: 12 | K33: bold | L33: center | M33: 0 | N33: default_from_click_area | P33: 0 | Q33: 0
A34: 완료 | B34: 서초 | C34: 서초 | D34: 서초역 | E34: 2 | F34: =ROUND(AVERAGEIF(Station_Visual_Nodes!$D$2:$D$2000,$B34,Station_Visual_Nodes!$I$2:$I$2000)+P34,0) | G34: =ROUND(AVERAGEIF(Station_Visual_Nodes!$D$2:$D$2000,$B34,Station_Visual_Nodes!$J$2:$J$2000)+Q34,0) | H34: =F34/5120*100 | I34: =G34/2880*100 | J34: 10.5 | K34: normal | L34: center | M34: 0 | N34: default_from_click_area | P34: 0 | Q34: 0
A35: 완료 | B35: 방배 | C35: 방배 | D35: 방배역 | E35: 2 | F35: =ROUND(AVERAGEIF(Station_Visual_Nodes!$D$2:$D$2000,$B35,Station_Visual_Nodes!$I$2:$I$2000)+P35,0) | G35: =ROUND(AVERAGEIF(Station_Visual_Nodes!$D$2:$D$2000,$B35,Station_Visual_Nodes!$J$2:$J$2000)+Q35,0) | H35: =F35/5120*100 | I35: =G35/2880*100 | J35: 10.5 | K35: normal | L35: center | M35: 0 | N35: default_from_click_area | P35: 0 | Q35: 0
A36: 완료 | B36: 사당 | C36: 사당 | D36: 사당역 | E36: 2,4 | F36: =ROUND(AVERAGEIF(Station_Visual_Nodes!$D$2:$D$2000,$B36,Station_Visual_Nodes!$I$2:$I$2000)+P36,0) | G36: =ROUND(AVERAGEIF(Station_Visual_Nodes!$D$2:$D$2000,$B36,Station_Visual_Nodes!$J$2:$J$2000)+Q36,0) | H36: =F36/5120*100 | I36: =G36/2880*100 | J36: 12 | K36: bold | L36: center | M36: 0 | N36: default_from_click_area | P36: 0 | Q36: 0
A37: 완료 | B37: 낙성대 | C37: 낙성대 | D37: 낙성대역 | E37: 2 | F37: =ROUND(AVERAGEIF(Station_Visual_Nodes!$D$2:$D$2000,$B37,Station_Visual_Nodes!$I$2:$I$2000)+P37,0) | G37: =ROUND(AVERAGEIF(Station_Visual_Nodes!$D$2:$D$2000,$B37,Station_Visual_Nodes!$J$2:$J$2000)+Q37,0) | H37: =F37/5120*100 | I37: =G37/2880*100 | J37: 10.5 | K37: normal | L37: center | M37: 0 | N37: default_from_click_area | P37: 0 | Q37: 0
A38: 완료 | B38: 서울대입구 | C38: 서울대입구 | D38: 서울대입구역 | E38: 2 | F38: =ROUND(AVERAGEIF(Station_Visual_Nodes!$D$2:$D$2000,$B38,Station_Visual_Nodes!$I$2:$I$2000)+P38,0) | G38: =ROUND(AVERAGEIF(Station_Visual_Nodes!$D$2:$D$2000,$B38,Station_Visual_Nodes!$J$2:$J$2000)+Q38,0) | H38: =F38/5120*100 | I38: =G38/2880*100 | J38: 10.5 | K38: normal | L38: center | M38: 0 | N38: default_from_click_area | P38: 0 | Q38: 0
A39: 완료 | B39: 봉천 | C39: 봉천 | D39: 봉천역 | E39: 2 | F39: =ROUND(AVERAGEIF(Station_Visual_Nodes!$D$2:$D$2000,$B39,Station_Visual_Nodes!$I$2:$I$2000)+P39,0) | G39: =ROUND(AVERAGEIF(Station_Visual_Nodes!$D$2:$D$2000,$B39,Station_Visual_Nodes!$J$2:$J$2000)+Q39,0) | H39: =F39/5120*100 | I39: =G39/2880*100 | J39: 10.5 | K39: normal | L39: center | M39: 0 | N39: default_from_click_area | P39: 0 | Q39: 0
A40: 완료 | B40: 신림 | C40: 신림 | D40: 신림역 | E40: 2 | F40: =ROUND(AVERAGEIF(Station_Visual_Nodes!$D$2:$D$2000,$B40,Station_Visual_Nodes!$I$2:$I$2000)+P40,0) | G40: =ROUND(AVERAGEIF(Station_Visual_Nodes!$D$2:$D$2000,$B40,Station_Visual_Nodes!$J$2:$J$2000)+Q40,0) | H40: =F40/5120*100 | I40: =G40/2880*100 | J40: 10.5 | K40: normal | L40: center | M40: 0 | N40: default_from_click_area | P40: 0 | Q40: 0
...

Sheet Map_Layer_Order
A1: layer_order | B1: layer_name | C1: source_sheet | D1: render_object | E1: note
A2: 1 | B2: line_paths | C2: Line_Sequences + Station_Visual_Nodes | D2: polyline/path | E2: 노선별 visual_node_id 좌표를 path_order 순서로 연결
A3: 2 | B3: transfer_connectors | C3: Transfer_Links | D3: line/path | E3: 환승역의 노선별 visual node를 얇은 회색 연결선으로 연결
A4: 3 | B4: station_markers | C4: Station_Visual_Nodes | D4: circle | E4: 지도에 보이는 역 점. 환승역은 노선별로 여러 점 가능
A5: 4 | B5: station_labels | C5: Station_Labels | D5: text | E5: 역명 라벨. station_key 기준으로 역당 1개 권장
A6: 5 | B6: route_highlight | C6: routing result | D6: path overlay | E6: 추천 경로 구간만 굵게 강조
A7: 6 | B7: origin_destination_highlight | C7: session_state | D7: halo/circle | E7: 출발역/도착역 강조
A8: 7 | B8: click_hitboxes | C8: Station_Click_Areas | D8: transparent circle | E8: 사용자 클릭 판정. 보이는 점보다 큰 투명 영역

Sheet Sources
A1: source_name | B1: url | C1: usage_note
A2: 서울교통공사_자치구별지하철역정보 | B2: https://www.data.go.kr/data/15081868/fileData.do | C2: 서울교통공사 관리 역 정보의 공식 공공데이터. 역명/호선 검증 참고.
A3: 서울교통공사_역간거리 | B3: https://data.seoul.go.kr/dataList/OA-12034/S/1/datasetView.do | C3: 서울교통공사 1~8호선 역간 거리 및 소요시간 데이터. 노선 순서/연결 검증 참고.
A4: 사용자 지정 프로젝트 범위 | B4: 현재 대화에서 사용자가 제공한 프로젝트 구간 | C4: 본 워크북은 사용자가 제공한 MetroCalm 프로젝트 범위에 맞춰 역 목록을 정리함.
A5: 서울메트로9호선_역사정보 | B5: 철도데이터포털(KRIC) 서울시메트로9호선주식회사 제공 (2026-05-31) | C5: 9호선 38역 역번호·위경도·승강장 유형. 역 순서 검증
A6: v1 좌표 워크북 (1~8호선) | B6: data/master/archive/ (보관) | C6: 1~8호선 좌표의 원본. 방화·개화산 좌표는 v2.6 에서 사용자가 조정
A7: 9호선 좌표 | B7: 사용자 직접 입력 (2026-10) | C7: 9호선 38역 x_px, y_px

Sheet 변경_기록
A1: 구분 | B1: 내용
A2: 확인 필요 | B2: 종합운동장_L2 — 다른 역(봉은사)과 좌표가 같음 — 확인 필요
A3: 확인 필요 | B3: 동작_L4 — 다른 역(흑석)과 좌표가 같음 — 확인 필요
A4: 확인 필요 | B4: 흑석_L9 — 다른 역(동작)과 좌표가 같음 — 확인 필요
A5: 확인 필요 | B5: 동작_L9 — 다른 역(흑석)과 좌표가 같음 — 확인 필요
A6: 확인 필요 | B6: 봉은사_L9 — 다른 역(종합운동장)과 좌표가 같음 — 확인 필요
A7: 확인 필요 | B7: 종합운동장_L9 — 다른 역(봉은사)과 좌표가 같음 — 확인 필요
A8: 1~8호선 좌표 변경 | B8: 방화_L5: (788, 828) → (788, 800)
A9: 1~8호선 좌표 변경 | B9: 개화산_L5: (788, 900) → (788, 884)
A10: 정리 | B10: AI_Handoff_Prompt·Project_Scope(→ Lines)·9호선 입력도우미 시트 제거, 안내 갱신 (5120×2880 기준)
