Workbook

Sheet Guide
A1: MetroCalm 벡터 노선도 좌표 작업 파일
A2: 목표 | B2: 사용자 선택용 station_key, 지도 렌더링용 visual_node_id, 역명 label, 클릭 hitbox를 분리해서 관리합니다.
A3: 작업 순서 1 | B3: Station_Visual_Nodes에서 각 visual_node_id별 x_px, y_px를 Inkscape/Figma 기준 픽셀로 입력합니다. 환승역은 노선별로 여러 좌표를 둡니다.
A4: 작업 순서 2 | B4: Station_Click_Areas의 click_x/y는 visual node 평균으로 자동 계산됩니다. 복잡한 환승역만 수동 override하세요.
A5: 작업 순서 3 | B5: Station_Labels의 label_x/y는 click area 기준으로 자동 계산됩니다. 역명이 겹치는 곳만 수동 보정하세요.
A6: 작업 순서 4 | B6: Line_Sequences는 노선 렌더링 순서입니다. station_key가 아니라 visual_node_id 기준으로 선을 연결합니다.
A7: 작업 순서 5 | B7: Transfer_Links는 환승역 내부 연결선입니다. 보이는 연결선일 뿐, 실제 환승 시간 평가는 별도 데이터로 유지합니다.
A8: 핵심 원칙 | B8: 사용자 화면: station_key / 지도 렌더링: visual_node_id / 내부 라우팅: station_uid. 세 계층을 혼동하지 않습니다.
A9: 이미지 기준 크기 | B9: Config 시트의 image_width_px=4900, image_height_px=2757 기준입니다. 이미지 크기가 바뀌면 Config만 수정하세요.
A10: 클릭 UX | B10: 정확한 픽셀을 클릭하지 않아도 되도록 Station_Click_Areas의 투명 hitbox를 최상단 레이어에 둡니다.

Sheet Config
A1: parameter | B1: value | C1: note
A2: image_width_px | B2: 5120 | C2: 원본/작업 기준 이미지 가로 픽셀. x_pct 계산 기준
A3: image_height_px | B3: 2880 | C3: 원본/작업 기준 이미지 세로 픽셀. y_pct 계산 기준
A4: default_general_marker_radius_px | B4: 10 | C4: 지도에 보이는 일반역 원 반경
A5: default_transfer_marker_radius_px | B5: 12 | C5: 지도에 보이는 환승역 visual node 반경
A6: default_general_click_radius_px | B6: 24 | C6: 일반역 클릭 hitbox 반경
A7: default_transfer_click_radius_px | B7: 48 | C7: 2개 노선 환승역 클릭 hitbox 반경
A8: default_complex_transfer_click_radius_px | B8: 56 | C8: 3개 이상 노선 환승역 클릭 hitbox 반경
A9: coordinate_origin | B9: top-left | C9: 좌표 원점은 이미지 좌상단
A10: coordinate_unit | B10: pixel | C10: x_px, y_px는 픽셀 기준. x_pct, y_pct는 자동 계산
A11: final_render_target | B11: SVG or Plotly vector map | C11: PNG 배경이 아니라 좌표 기반 벡터 렌더링에도 사용 가능

Sheet Station_Display_Master
A1: station_no | B1: station_key | C1: station_name | D1: display_name | E1: available_lines | F1: candidate_station_uids | G1: project_branches | H1: is_transfer_station | I1: is_event_station | J1: alias_or_note | K1: memo
A2: 1 | B2: 서울역 | C2: 서울역 | D2: 서울역 | E2: 1,4 | G2: 1:main;4:main | H2: TRUE | I2: FALSE
A3: 2 | B3: 시청 | C3: 시청 | D3: 시청역 | E3: 1,2 | G3: 1:main;2:main | H3: TRUE | I3: TRUE
A4: 3 | B4: 종각 | C4: 종각 | D4: 종각역 | E4: 1 | G4: 1:main | H4: FALSE | I4: TRUE
A5: 4 | B5: 종로3가 | C5: 종로3가 | D5: 종로3가역 | E5: 1,3,5 | G5: 1:main;3:main;5:common | H5: TRUE | I5: FALSE
A6: 5 | B6: 종로5가 | C6: 종로5가 | D6: 종로5가역 | E6: 1 | G6: 1:main | H6: FALSE | I6: FALSE
A7: 6 | B7: 동대문 | C7: 동대문 | D7: 동대문역 | E7: 1,4 | G7: 1:main;4:main | H7: TRUE | I7: FALSE
A8: 7 | B8: 동묘앞 | C8: 동묘앞 | D8: 동묘앞역 | E8: 1,6 | G8: 1:main;6:main | H8: TRUE | I8: FALSE
A9: 8 | B9: 신설동 | C9: 신설동 | D9: 신설동역 | E9: 1,2 | G9: 1:main;2:seongsu_branch | H9: TRUE | I9: FALSE
A10: 9 | B10: 제기동 | C10: 제기동 | D10: 제기동역 | E10: 1 | G10: 1:main | H10: FALSE | I10: FALSE
A11: 10 | B11: 청량리 | C11: 청량리 | D11: 청량리역 | E11: 1 | G11: 1:main | H11: FALSE | I11: FALSE | J11: 청량리(서울시립대입구)
A12: 11 | B12: 을지로입구 | C12: 을지로입구 | D12: 을지로입구역 | E12: 2 | G12: 2:main | H12: FALSE | I12: FALSE
A13: 12 | B13: 을지로3가 | C13: 을지로3가 | D13: 을지로3가역 | E13: 2,3 | G13: 2:main;3:main | H13: TRUE | I13: FALSE
A14: 13 | B14: 을지로4가 | C14: 을지로4가 | D14: 을지로4가역 | E14: 2,5 | G14: 2:main;5:common | H14: TRUE | I14: FALSE
A15: 14 | B15: 동대문역사문화공원 | C15: 동대문역사문화공원 | D15: 동대문역사문화공원역 | E15: 2,4,5 | G15: 2:main;4:main;5:common | H15: TRUE | I15: FALSE | J15: 동대문역사문화공원(DDP)
A16: 15 | B16: 신당 | C16: 신당 | D16: 신당역 | E16: 2,6 | G16: 2:main;6:main | H16: TRUE | I16: FALSE
A17: 16 | B17: 상왕십리 | C17: 상왕십리 | D17: 상왕십리역 | E17: 2 | G17: 2:main | H17: FALSE | I17: FALSE
A18: 17 | B18: 왕십리 | C18: 왕십리 | D18: 왕십리역 | E18: 2,5 | G18: 2:main;5:common | H18: TRUE | I18: FALSE
A19: 18 | B19: 한양대 | C19: 한양대 | D19: 한양대역 | E19: 2 | G19: 2:main | H19: FALSE | I19: TRUE
A20: 19 | B20: 뚝섬 | C20: 뚝섬 | D20: 뚝섬역 | E20: 2 | G20: 2:main | H20: FALSE | I20: FALSE
A21: 20 | B21: 성수 | C21: 성수 | D21: 성수역 | E21: 2 | G21: 2:main;2:seongsu_branch | H21: FALSE | I21: FALSE
A22: 21 | B22: 건대입구 | C22: 건대입구 | D22: 건대입구역 | E22: 2,7 | G22: 2:main;7:main | H22: TRUE | I22: TRUE
A23: 22 | B23: 구의 | C23: 구의 | D23: 구의역 | E23: 2 | G23: 2:main | H23: FALSE | I23: FALSE
A24: 23 | B24: 강변 | C24: 강변 | D24: 강변역 | E24: 2 | G24: 2:main | H24: FALSE | I24: FALSE
A25: 24 | B25: 잠실나루 | C25: 잠실나루 | D25: 잠실나루역 | E25: 2 | G25: 2:main | H25: FALSE | I25: FALSE
A26: 25 | B26: 잠실 | C26: 잠실 | D26: 잠실역 | E26: 2,8 | G26: 2:main;8:main | H26: TRUE | I26: FALSE
A27: 26 | B27: 잠실새내 | C27: 잠실새내 | D27: 잠실새내역 | E27: 2 | G27: 2:main | H27: FALSE | I27: FALSE
... A68: 67 | B68: 독립문 | C68: 독립문 | D68: 독립문역 | E68: 3 | G68: 3:main | H68: FALSE | I68: FALSE
A69: 68 | B69: 경복궁 | C69: 경복궁 | D69: 경복궁역 | E69: 3 | G69: 3:main | H69: FALSE | I69: TRUE | J69: 경복궁(정부서울청사)
A70: 69 | B70: 안국 | C70: 안국 | D70: 안국역 | E70: 3 | G70: 3:main | H70: FALSE | I70: FALSE
A71: 70 | B71: 충무로 | C71: 충무로 | D71: 충무로역 | E71: 3,4 | G71: 3:main;4:main | H71: TRUE | I71: FALSE
A72: 71 | B72: 동대입구 | C72: 동대입구 | D72: 동대입구역 | E72: 3 | G72: 3:main | H72: FALSE | I72: TRUE
A73: 72 | B73: 약수 | C73: 약수 | D73: 약수역 | E73: 3,6 | G73: 3:main;6:main | H73: TRUE | I73: FALSE
A74: 73 | B74: 금호 | C74: 금호 | D74: 금호역 | E74: 3 | G74: 3:main | H74: FALSE | I74: FALSE
A75: 74 | B75: 옥수 | C75: 옥수 | D75: 옥수역 | E75: 3 | G75: 3:main | H75: FALSE | I75: FALSE
A76: 75 | B76: 압구정 | C76: 압구정 | D76: 압구정역 | E76: 3 | G76: 3:main | H76: FALSE | I76: FALSE
A77: 76 | B77: 신사 | C77: 신사 | D77: 신사역 | E77: 3 | G77: 3:main | H77: FALSE | I77: FALSE
A78: 77 | B78: 잠원 | C78: 잠원 | D78: 잠원역 | E78: 3 | G78: 3:main | H78: FALSE | I78: FALSE
A79: 78 | B79: 고속터미널 | C79: 고속터미널 | D79: 고속터미널역 | E79: 3,7 | G79: 3:main;7:main | H79: TRUE | I79: FALSE
A80: 79 | B80: 남부터미널 | C80: 남부터미널 | D80: 남부터미널역 | E80: 3 | G80: 3:main | H80: FALSE | I80: FALSE
...

Sheet Station_Visual_Nodes
A1: mark_status | B1: visual_node_no | C1: visual_node_id | D1: station_key | E1: station_name | F1: display_name | G1: line_id | H1: branch_codes | I1: x_px | J1: y_px | K1: x_pct | L1: y_pct | M1: marker_radius_px | N1: is_transfer_station | O1: is_branch_node | P1: label_owner | Q1: alias_or_note | R1: memo
A2: =IF(OR(I2="",J2=""),"미작업","완료") -> 완료 | B2: 1 | C2: 서울역_L1 | D2: 서울역 | E2: 서울역 | F2: 서울역 | G2: 1 | H2: main | I2: 1916 | J2: 1308 | K2: =IF(I2="","",I2/Config!$B$2*100) -> 37.421875 | L2: =IF(J2="","",J2/Config!$B$3*100) -> 45.416667 | M2: 12 | N2: TRUE | O2: TRUE | P2: TRUE
A3: =IF(OR(I3="",J3=""),"미작업","완료") -> 완료 | B3: 2 | C3: 시청_L1 | D3: 시청 | E3: 시청 | F3: 시청역 | G3: 1 | H3: main | I3: 1916 | J3: 1144 | K3: =IF(I3="","",I3/Config!$B$2*100) -> 37.421875 | L3: =IF(J3="","",J3/Config!$B$3*100) -> 39.722222 | M3: 12 | N3: TRUE | O3: FALSE | P3: TRUE
A4: =IF(OR(I4="",J4=""),"미작업","완료") -> 완료 | B4: 3 | C4: 종각_L1 | D4: 종각 | E4: 종각 | F4: 종각역 | G4: 1 | H4: main | I4: 1916 | J4: 1048 | K4: =IF(I4="","",I4/Config!$B$2*100) -> 37.421875 | L4: =IF(J4="","",J4/Config!$B$3*100) -> 36.388889 | M4: 10 | N4: FALSE | O4: FALSE | P4: TRUE
A5: =IF(OR(I5="",J5=""),"미작업","완료") -> 완료 | B5: 4 | C5: 종로3가_L1 | D5: 종로3가 | E5: 종로3가 | F5: 종로3가역 | G5: 1 | H5: main | I5: 2084 | J5: 980 | K5: =IF(I5="","",I5/Config!$B$2*100) -> 40.703125 | L5: =IF(J5="","",J5/Config!$B$3*100) -> 34.027778 | M5: 12 | N5: TRUE | O5: FALSE | P5: TRUE
A6: =IF(OR(I6="",J6=""),"미작업","완료") -> 완료 | B6: 5 | C6: 종로5가_L1 | D6: 종로5가 | E6: 종로5가 | F6: 종로5가역 | G6: 1 | H6: main | I6: 2240 | J6: 980 | K6: =IF(I6="","",I6/Config!$B$2*100) -> 43.75 | L6: =IF(J6="","",J6/Config!$B$3*100) -> 34.027778 | M6: 10 | N6: FALSE | O6: FALSE | P6: TRUE
A7: =IF(OR(I7="",J7=""),"미작업","완료") -> 완료 | B7: 6 | C7: 동대문_L1 | D7: 동대문 | E7: 동대문 | F7: 동대문역 | G7: 1 | H7: main | I7: 2328 | J7: 980 | K7: =IF(I7="","",I7/Config!$B$2*100) -> 45.46875 | L7: =IF(J7="","",J7/Config!$B$3*100) -> 34.027778 | M7: 12 | N7: TRUE | O7: FALSE | P7: TRUE
A8: =IF(OR(I8="",J8=""),"미작업","완료") -> 완료 | B8: 7 | C8: 동묘앞_L1 | D8: 동묘앞 | E8: 동묘앞 | F8: 동묘앞역 | G8: 1 | H8: main | I8: 2528 | J8: 980 | K8: =IF(I8="","",I8/Config!$B$2*100) -> 49.375 | L8: =IF(J8="","",J8/Config!$B$3*100) -> 34.027778 | M8: 12 | N8: TRUE | O8: FALSE | P8: TRUE
A9: =IF(OR(I9="",J9=""),"미작업","완료") -> 완료 | B9: 8 | C9: 신설동_L1 | D9: 신설동 | E9: 신설동 | F9: 신설동역 | G9: 1 | H9: main | I9: 2712 | J9: 980 | K9: =IF(I9="","",I9/Config!$B$2*100) -> 52.96875 | L9: =IF(J9="","",J9/Config!$B$3*100) -> 34.027778 | M9: 12 | N9: TRUE | O9: FALSE | P9: TRUE
A10: =IF(OR(I10="",J10=""),"미작업","완료") -> 완료 | B10: 9 | C10: 제기동_L1 | D10: 제기동 | E10: 제기동 | F10: 제기동역 | G10: 1 | H10: main | I10: 2864 | J10: 980 | K10: =IF(I10="","",I10/Config!$B$2*100) -> 55.9375 | L10: =IF(J10="","",J10/Config!$B$3*100) -> 34.027778 | M10: 10 | N10: FALSE | O10: FALSE | P10: TRUE
A11: =IF(OR(I11="",J11=""),"미작업","완료") -> 완료 | B11: 10 | C11: 청량리_L1 | D11: 청량리 | E11: 청량리 | F11: 청량리역 | G11: 1 | H11: main | I11: 3020 | J11: 980 | K11: =IF(I11="","",I11/Config!$B$2*100) -> 58.984375 | L11: =IF(J11="","",J11/Config!$B$3*100) -> 34.027778 | M11: 10 | N11: FALSE | O11: TRUE | P11: TRUE | Q11: 청량리(서울시립대입구)
A12: =IF(OR(I12="",J12=""),"미작업","완료") -> 완료 | B12: 11 | C12: 시청_L2 | D12: 시청 | E12: 시청 | F12: 시청역 | G12: 2 | H12: main | I12: 1916 | J12: 1144 | K12: =IF(I12="","",I12/Config!$B$2*100) -> 37.421875 | L12: =IF(J12="","",J12/Config!$B$3*100) -> 39.722222 | M12: 12 | N12: TRUE | O12: TRUE | P12: FALSE
A13: =IF(OR(I13="",J13=""),"미작업","완료") -> 완료 | B13: 12 | C13: 신설동_L2 | D13: 신설동 | E13: 신설동 | F13: 신설동역 | G13: 2 | H13: seongsu_branch | I13: 2712 | J13: 980 | K13: =IF(I13="","",I13/Config!$B$2*100) -> 52.96875 | L13: =IF(J13="","",J13/Config!$B$3*100) -> 34.027778 | M13: 12 | N13: TRUE | O13: TRUE | P13: FALSE
A14: =IF(OR(I14="",J14=""),"미작업","완료") -> 완료 | B14: 13 | C14: 을지로입구_L2 | D14: 을지로입구 | E14: 을지로입구 | F14: 을지로입구역 | G14: 2 | H14: main | I14: 2000 | J14: 1144 | K14: =IF(I14="","",I14/Config!$B$2*100) -> 39.0625 | L14: =IF(J14="","",J14/Config!$B$3*100) -> 39.722222 | M14: 10 | N14: FALSE | O14: FALSE | P14: TRUE
A15: =IF(OR(I15="",J15=""),"미작업","완료") -> 완료 | B15: 14 | C15: 을지로3가_L2 | D15: 을지로3가 | E15: 을지로3가 | F15: 을지로3가역 | G15: 2 | H15: main | I15: 2084 | J15: 1144 | K15: =IF(I15="","",I15/Config!$B$2*100) -> 40.703125 | L15: =IF(J15="","",J15/Config!$B$3*100) -> 39.722222 | M15: 12 | N15: TRUE | O15: FALSE | P15: TRUE
A16: =IF(OR(I16="",J16=""),"미작업","완료") -> 완료 | B16: 15 | C16: 을지로4가_L2 | D16: 을지로4가 | E16: 을지로4가 | F16: 을지로4가역 | G16: 2 | H16: main | I16: 2200 | J16: 1144 | K16: =IF(I16="","",I16/Config!$B$2*100) -> 42.96875 | L16: =IF(J16="","",J16/Config!$B$3*100) -> 39.722222 | M16: 12 | N16: TRUE | O16: FALSE | P16: TRUE
A17: =IF(OR(I17="",J17=""),"미작업","완료") -> 완료 | B17: 16 | C17: 동대문역사문화공원_L2 | D17: 동대문역사문화공원 | E17: 동대문역사문화공원 | F17: 동대문역사문화공원역 | G17: 2 | H17: main | I17: 2328 | J17: 1144 | K17: =IF(I17="","",I17/Config!$B$2*100) -> 45.46875 | L17: =IF(J17="","",J17/Config!$B$3*100) -> 39.722222 | M17: 12 | N17: TRUE | O17: FALSE | P17: TRUE | Q17: 동대문역사문화공원(DDP)
A18: =IF(OR(I18="",J18=""),"미작업","완료") -> 완료 | B18: 17 | C18: 신당_L2 | D18: 신당 | E18: 신당 | F18: 신당역 | G18: 2 | H18: main | I18: 2528 | J18: 1144 | K18: =IF(I18="","",I18/Config!$B$2*100) -> 49.375 | L18: =IF(J18="","",J18/Config!$B$3*100) -> 39.722222 | M18: 12 | N18: TRUE | O18: FALSE | P18: TRUE
A19: =IF(OR(I19="",J19=""),"미작업","완료") -> 완료 | B19: 18 | C19: 상왕십리_L2 | D19: 상왕십리 | E19: 상왕십리 | F19: 상왕십리역 | G19: 2 | H19: main | I19: 2628 | J19: 1144 | K19: =IF(I19="","",I19/Config!$B$2*100) -> 51.328125 | L19: =IF(J19="","",J19/Config!$B$3*100) -> 39.722222 | M19: 10 | N19: FALSE | O19: FALSE | P19: TRUE
A20: =IF(OR(I20="",J20=""),"미작업","완료") -> 완료 | B20: 19 | C20: 왕십리_L2 | D20: 왕십리 | E20: 왕십리 | F20: 왕십리역 | G20: 2 | H20: main | I20: 2740 | J20: 1144 | K20: =IF(I20="","",I20/Config!$B$2*100) -> 53.515625 | L20: =IF(J20="","",J20/Config!$B$3*100) -> 39.722222 | M20: 12 | N20: TRUE | O20: FALSE | P20: TRUE
A21: =IF(OR(I21="",J21=""),"미작업","완료") -> 완료 | B21: 20 | C21: 한양대_L2 | D21: 한양대 | E21: 한양대 | F21: 한양대역 | G21: 2 | H21: main | I21: 2864 | J21: 1188 | K21: =IF(I21="","",I21/Config!$B$2*100) -> 55.9375 | L21: =IF(J21="","",J21/Config!$B$3*100) -> 41.25 | M21: 10 | N21: FALSE | O21: FALSE | P21: TRUE
A22: =IF(OR(I22="",J22=""),"미작업","완료") -> 완료 | B22: 21 | C22: 뚝섬_L2 | D22: 뚝섬 | E22: 뚝섬 | F22: 뚝섬역 | G22: 2 | H22: main | I22: 2920 | J22: 1244 | K22: =IF(I22="","",I22/Config!$B$2*100) -> 57.03125 | L22: =IF(J22="","",J22/Config!$B$3*100) -> 43.194444 | M22: 10 | N22: FALSE | O22: FALSE | P22: TRUE
A23: =IF(OR(I23="",J23=""),"미작업","완료") -> 완료 | B23: 22 | C23: 성수_L2 | D23: 성수 | E23: 성수 | F23: 성수역 | G23: 2 | H23: main;seongsu_branch | I23: 2972 | J23: 1294 | K23: =IF(I23="","",I23/Config!$B$2*100) -> 58.046875 | L23: =IF(J23="","",J23/Config!$B$3*100) -> 44.930556 | M23: 10 | N23: FALSE | O23: TRUE | P23: TRUE
A24: =IF(OR(I24="",J24=""),"미작업","완료") -> 완료 | B24: 23 | C24: 건대입구_L2 | D24: 건대입구 | E24: 건대입구 | F24: 건대입구역 | G24: 2 | H24: main | I24: 2972 | J24: 1468 | K24: =IF(I24="","",I24/Config!$B$2*100) -> 58.046875 | L24: =IF(J24="","",J24/Config!$B$3*100) -> 50.972222 | M24: 12 | N24: TRUE | O24: FALSE | P24: TRUE
A25: =IF(OR(I25="",J25=""),"미작업","완료") -> 완료 | B25: 24 | C25: 구의_L2 | D25: 구의 | E25: 구의 | F25: 구의역 | G25: 2 | H25: main | I25: 2972 | J25: 1552 | K25: =IF(I25="","",I25/Config!$B$2*100) -> 58.046875 | L25: =IF(J25="","",J25/Config!$B$3*100) -> 53.888889 | M25: 10 | N25: FALSE | O25: FALSE | P25: TRUE
A26: =IF(OR(I26="",J26=""),"미작업","완료") -> 완료 | B26: 25 | C26: 강변_L2 | D26: 강변 | E26: 강변 | F26: 강변역 | G26: 2 | H26: main | I26: 2972 | J26: 1628 | K26: =IF(I26="","",I26/Config!$B$2*100) -> 58.046875 | L26: =IF(J26="","",J26/Config!$B$3*100) -> 56.527778 | M26: 10 | N26: FALSE | O26: FALSE | P26: TRUE
A27: =IF(OR(I27="",J27=""),"미작업","완료") -> 완료 | B27: 26 | C27: 잠실나루_L2 | D27: 잠실나루 | E27: 잠실나루 | F27: 잠실나루역 | G27: 2 | H27: main | I27: 2972 | J27: 1708 | K27: =IF(I27="","",I27/Config!$B$2*100) -> 58.046875 | L27: =IF(J27="","",J27/Config!$B$3*100) -> 59.305556 | M27: 10 | N27: FALSE | O27: FALSE | P27: TRUE
A28: =IF(OR(I28="",J28=""),"미작업","완료") -> 완료 | B28: 27 | C28: 잠실_L2 | D28: 잠실 | E28: 잠실 | F28: 잠실역 | G28: 2 | H28: main | I28: 2972 | J28: 1800 | K28: =IF(I28="","",I28/Config!$B$2*100) -> 58.046875 | L28: =IF(J28="","",J28/Config!$B$3*100) -> 62.5 | M28: 12 | N28: TRUE | O28: FALSE | P28: TRUE
A29: =IF(OR(I29="",J29=""),"미작업","완료") -> 완료 | B29: 28 | C29: 잠실새내_L2 | D29: 잠실새내 | E29: 잠실새내 | F29: 잠실새내역 | G29: 2 | H29: main | I29: 2972 | J29: 1882 | K29: =IF(I29="","",I29/Config!$B$2*100) -> 58.046875 | L29: =IF(J29="","",J29/Config!$B$3*100) -> 65.347222 | M29: 10 | N29: FALSE | O29: FALSE | P29: TRUE
... A73: =IF(OR(I73="",J73=""),"미작업","완료") -> 완료 | B73: 72 | C73: 독립문_L3 | D73: 독립문 | E73: 독립문 | F73: 독립문역 | G73: 3 | H73: main | I73: 2084 | J73: 488 | K73: =IF(I73="","",I73/Config!$B$2*100) -> 40.703125 | L73: =IF(J73="","",J73/Config!$B$3*100) -> 16.944444 | M73: 10 | N73: FALSE | O73: FALSE | P73: TRUE
A74: =IF(OR(I74="",J74=""),"미작업","완료") -> 완료 | B74: 73 | C74: 경복궁_L3 | D74: 경복궁 | E74: 경복궁 | F74: 경복궁역 | G74: 3 | H74: main | I74: 2084 | J74: 648 | K74: =IF(I74="","",I74/Config!$B$2*100) -> 40.703125 | L74: =IF(J74="","",J74/Config!$B$3*100) -> 22.5 | M74: 10 | N74: FALSE | O74: FALSE | P74: TRUE | Q74: 경복궁(정부서울청사)
A75: =IF(OR(I75="",J75=""),"미작업","완료") -> 완료 | B75: 74 | C75: 안국_L3 | D75: 안국 | E75: 안국 | F75: 안국역 | G75: 3 | H75: main | I75: 2084 | J75: 808 | K75: =IF(I75="","",I75/Config!$B$2*100) -> 40.703125 | L75: =IF(J75="","",J75/Config!$B$3*100) -> 28.055556 | M75: 10 | N75: FALSE | O75: FALSE | P75: TRUE
A76: =IF(OR(I76="",J76=""),"미작업","완료") -> 완료 | B76: 75 | C76: 충무로_L3 | D76: 충무로 | E76: 충무로 | F76: 충무로역 | G76: 3 | H76: main | I76: 2328 | J76: 1244 | K76: =IF(I76="","",I76/Config!$B$2*100) -> 45.46875 | L76: =IF(J76="","",J76/Config!$B$3*100) -> 43.194444 | M76: 12 | N76: TRUE | O76: FALSE | P76: TRUE
A77: =IF(OR(I77="",J77=""),"미작업","완료") -> 완료 | B77: 76 | C77: 동대입구_L3 | D77: 동대입구 | E77: 동대입구 | F77: 동대입구역 | G77: 3 | H77: main | I77: 2404 | J77: 1356 | K77: =IF(I77="","",I77/Config!$B$2*100) -> 46.953125 | L77: =IF(J77="","",J77/Config!$B$3*100) -> 47.083333 | M77: 10 | N77: FALSE | O77: FALSE | P77: TRUE
A78: =IF(OR(I78="",J78=""),"미작업","완료") -> 완료 | B78: 77 | C78: 약수_L3 | D78: 약수 | E78: 약수 | F78: 약수역 | G78: 3 | H78: main | I78: 2480 | J78: 1476 | K78: =IF(I78="","",I78/Config!$B$2*100) -> 48.4375 | L78: =IF(J78="","",J78/Config!$B$3*100) -> 51.25 | M78: 12 | N78: TRUE | O78: FALSE | P78: TRUE
A79: =IF(OR(I79="",J79=""),"미작업","완료") -> 완료 | B79: 78 | C79: 금호_L3 | D79: 금호 | E79: 금호 | F79: 금호역 | G79: 3 | H79: main | I79: 2480 | J79: 1556 | K79: =IF(I79="","",I79/Config!$B$2*100) -> 48.4375 | L79: =IF(J79="","",J79/Config!$B$3*100) -> 54.027778 | M79: 10 | N79: FALSE | O79: FALSE | P79: TRUE
A80: =IF(OR(I80="",J80=""),"미작업","완료") -> 완료 | B80: 79 | C80: 옥수_L3 | D80: 옥수 | E80: 옥수 | F80: 옥수역 | G80: 3 | H80: main | I80: 2480 | J80: 1636 | K80: =IF(I80="","",I80/Config!$B$2*100) -> 48.4375 | L80: =IF(J80="","",J80/Config!$B$3*100) -> 56.805556 | M80: 10 | N80: FALSE | O80: FALSE | P80: TRUE
A81: =IF(OR(I81="",J81=""),"미작업","완료") -> 완료 | B81: 80 | C81: 압구정_L3 | D81: 압구정 | E81: 압구정 | F81: 압구정역 | G81: 3 | H81: main | I81: 2480 | J81: 1760 | K81: =IF(I81="","",I81/Config!$B$2*100) -> 48.4375 | L81: =IF(J81="","",J81/Config!$B$3*100) -> 61.111111 | M81: 10 | N81: FALSE | O81: FALSE | P81: TRUE
A82: =IF(OR(I82="",J82=""),"미작업","완료") -> 완료 | B82: 81 | C82: 신사_L3 | D82: 신사 | E82: 신사 | F82: 신사역 | G82: 3 | H82: main | I82: 2480 | J82: 1828 | K82: =IF(I82="","",I82/Config!$B$2*100) -> 48.4375 | L82: =IF(J82="","",J82/Config!$B$3*100) -> 63.472222 | M82: 10 | N82: FALSE | O82: FALSE | P82: TRUE
A83: =IF(OR(I83="",J83=""),"미작업","완료") -> 완료 | B83: 82 | C83: 잠원_L3 | D83: 잠원 | E83: 잠원 | F83: 잠원역 | G83: 3 | H83: main | I83: 2480 | J83: 1884 | K83: =IF(I83="","",I83/Config!$B$2*100) -> 48.4375 | L83: =IF(J83="","",J83/Config!$B$3*100) -> 65.416667 | M83: 10 | N83: FALSE | O83: FALSE | P83: TRUE
...

Sheet Station_Click_Areas
A1: mark_status | B1: station_key | C1: station_name | D1: display_name | E1: available_lines | F1: click_x_px | G1: click_y_px | H1: click_x_pct | I1: click_y_pct | J1: click_radius_px | K1: click_shape | L1: source_method | M1: manual_override_note
A2: =IF(OR(F2="",G2=""),"미작업","완료") -> 완료 | B2: 서울역 | C2: 서울역 | D2: 서울역 | E2: 1,4 | F2: =IFERROR(AVERAGEIF(Station_Visual_Nodes!$D:$D,B2,Station_Visual_Nodes!$I:$I),"") -> 1916 | G2: =IFERROR(AVERAGEIF(Station_Visual_Nodes!$D:$D,B2,Station_Visual_Nodes!$J:$J),"") -> 1308 | H2: =IF(F2="","",F2/Config!$B$2*100) -> 37.421875 | I2: =IF(G2="","",G2/Config!$B$3*100) -> 45.416667 | J2: 42 | K2: circle | L2: auto_from_visual_nodes_avg
A3: =IF(OR(F3="",G3=""),"미작업","완료") -> 완료 | B3: 시청 | C3: 시청 | D3: 시청역 | E3: 1,2 | F3: =IFERROR(AVERAGEIF(Station_Visual_Nodes!$D:$D,B3,Station_Visual_Nodes!$I:$I),"") -> 1916 | G3: =IFERROR(AVERAGEIF(Station_Visual_Nodes!$D:$D,B3,Station_Visual_Nodes!$J:$J),"") -> 1144 | H3: =IF(F3="","",F3/Config!$B$2*100) -> 37.421875 | I3: =IF(G3="","",G3/Config!$B$3*100) -> 39.722222 | J3: 42 | K3: circle | L3: auto_from_visual_nodes_avg
A4: =IF(OR(F4="",G4=""),"미작업","완료") -> 완료 | B4: 종각 | C4: 종각 | D4: 종각역 | E4: 1 | F4: =IFERROR(AVERAGEIF(Station_Visual_Nodes!$D:$D,B4,Station_Visual_Nodes!$I:$I),"") -> 1916 | G4: =IFERROR(AVERAGEIF(Station_Visual_Nodes!$D:$D,B4,Station_Visual_Nodes!$J:$J),"") -> 1048 | H4: =IF(F4="","",F4/Config!$B$2*100) -> 37.421875 | I4: =IF(G4="","",G4/Config!$B$3*100) -> 36.388889 | J4: 24 | K4: circle | L4: auto_from_visual_nodes_avg
A5: =IF(OR(F5="",G5=""),"미작업","완료") -> 완료 | B5: 종로3가 | C5: 종로3가 | D5: 종로3가역 | E5: 1,3,5 | F5: =IFERROR(AVERAGEIF(Station_Visual_Nodes!$D:$D,B5,Station_Visual_Nodes!$I:$I),"") -> 2084 | G5: =IFERROR(AVERAGEIF(Station_Visual_Nodes!$D:$D,B5,Station_Visual_Nodes!$J:$J),"") -> 980 | H5: =IF(F5="","",F5/Config!$B$2*100) -> 40.703125 | I5: =IF(G5="","",G5/Config!$B$3*100) -> 34.027778 | J5: 52 | K5: circle | L5: auto_from_visual_nodes_avg
A6: =IF(OR(F6="",G6=""),"미작업","완료") -> 완료 | B6: 종로5가 | C6: 종로5가 | D6: 종로5가역 | E6: 1 | F6: =IFERROR(AVERAGEIF(Station_Visual_Nodes!$D:$D,B6,Station_Visual_Nodes!$I:$I),"") -> 2240 | G6: =IFERROR(AVERAGEIF(Station_Visual_Nodes!$D:$D,B6,Station_Visual_Nodes!$J:$J),"") -> 980 | H6: =IF(F6="","",F6/Config!$B$2*100) -> 43.75 | I6: =IF(G6="","",G6/Config!$B$3*100) -> 34.027778 | J6: 24 | K6: circle | L6: auto_from_visual_nodes_avg
A7: =IF(OR(F7="",G7=""),"미작업","완료") -> 완료 | B7: 동대문 | C7: 동대문 | D7: 동대문역 | E7: 1,4 | F7: =IFERROR(AVERAGEIF(Station_Visual_Nodes!$D:$D,B7,Station_Visual_Nodes!$I:$I),"") -> 2328 | G7: =IFERROR(AVERAGEIF(Station_Visual_Nodes!$D:$D,B7,Station_Visual_Nodes!$J:$J),"") -> 980 | H7: =IF(F7="","",F7/Config!$B$2*100) -> 45.46875 | I7: =IF(G7="","",G7/Config!$B$3*100) -> 34.027778 | J7: 42 | K7: circle | L7: auto_from_visual_nodes_avg
A8: =IF(OR(F8="",G8=""),"미작업","완료") -> 완료 | B8: 동묘앞 | C8: 동묘앞 | D8: 동묘앞역 | E8: 1,6 | F8: =IFERROR(AVERAGEIF(Station_Visual_Nodes!$D:$D,B8,Station_Visual_Nodes!$I:$I),"") -> 2528 | G8: =IFERROR(AVERAGEIF(Station_Visual_Nodes!$D:$D,B8,Station_Visual_Nodes!$J:$J),"") -> 980 | H8: =IF(F8="","",F8/Config!$B$2*100) -> 49.375 | I8: =IF(G8="","",G8/Config!$B$3*100) -> 34.027778 | J8: 42 | K8: circle | L8: auto_from_visual_nodes_avg
A9: =IF(OR(F9="",G9=""),"미작업","완료") -> 완료 | B9: 신설동 | C9: 신설동 | D9: 신설동역 | E9: 1,2 | F9: =IFERROR(AVERAGEIF(Station_Visual_Nodes!$D:$D,B9,Station_Visual_Nodes!$I:$I),"") -> 2712 | G9: =IFERROR(AVERAGEIF(Station_Visual_Nodes!$D:$D,B9,Station_Visual_Nodes!$J:$J),"") -> 980 | H9: =IF(F9="","",F9/Config!$B$2*100) -> 52.96875 | I9: =IF(G9="","",G9/Config!$B$3*100) -> 34.027778 | J9: 42 | K9: circle | L9: auto_from_visual_nodes_avg
A10: =IF(OR(F10="",G10=""),"미작업","완료") -> 완료 | B10: 제기동 | C10: 제기동 | D10: 제기동역 | E10: 1 | F10: =IFERROR(AVERAGEIF(Station_Visual_Nodes!$D:$D,B10,Station_Visual_Nodes!$I:$I),"") -> 2864 | G10: =IFERROR(AVERAGEIF(Station_Visual_Nodes!$D:$D,B10,Station_Visual_Nodes!$J:$J),"") -> 980 | H10: =IF(F10="","",F10/Config!$B$2*100) -> 55.9375 | I10: =IF(G10="","",G10/Config!$B$3*100) -> 34.027778 | J10: 24 | K10: circle | L10: auto_from_visual_nodes_avg
A11: =IF(OR(F11="",G11=""),"미작업","완료") -> 완료 | B11: 청량리 | C11: 청량리 | D11: 청량리역 | E11: 1 | F11: =IFERROR(AVERAGEIF(Station_Visual_Nodes!$D:$D,B11,Station_Visual_Nodes!$I:$I),"") -> 3020 | G11: =IFERROR(AVERAGEIF(Station_Visual_Nodes!$D:$D,B11,Station_Visual_Nodes!$J:$J),"") -> 980 | H11: =IF(F11="","",F11/Config!$B$2*100) -> 58.984375 | I11: =IF(G11="","",G11/Config!$B$3*100) -> 34.027778 | J11: 24 | K11: circle | L11: auto_from_visual_nodes_avg
A12: =IF(OR(F12="",G12=""),"미작업","완료") -> 완료 | B12: 을지로입구 | C12: 을지로입구 | D12: 을지로입구역 | E12: 2 | F12: =IFERROR(AVERAGEIF(Station_Visual_Nodes!$D:$D,B12,Station_Visual_Nodes!$I:$I),"") -> 2000 | G12: =IFERROR(AVERAGEIF(Station_Visual_Nodes!$D:$D,B12,Station_Visual_Nodes!$J:$J),"") -> 1144 | H12: =IF(F12="","",F12/Config!$B$2*100) -> 39.0625 | I12: =IF(G12="","",G12/Config!$B$3*100) -> 39.722222 | J12: 24 | K12: circle | L12: auto_from_visual_nodes_avg
A13: =IF(OR(F13="",G13=""),"미작업","완료") -> 완료 | B13: 을지로3가 | C13: 을지로3가 | D13: 을지로3가역 | E13: 2,3 | F13: =IFERROR(AVERAGEIF(Station_Visual_Nodes!$D:$D,B13,Station_Visual_Nodes!$I:$I),"") -> 2084 | G13: =IFERROR(AVERAGEIF(Station_Visual_Nodes!$D:$D,B13,Station_Visual_Nodes!$J:$J),"") -> 1144 | H13: =IF(F13="","",F13/Config!$B$2*100) -> 40.703125 | I13: =IF(G13="","",G13/Config!$B$3*100) -> 39.722222 | J13: 42 | K13: circle | L13: auto_from_visual_nodes_avg
... A241: =IF(OR(F241="",G241=""),"미작업","완료") -> 완료 | B241: 모란 | C241: 모란 | D241: 모란역 | E241: 8 | F241: =IFERROR(AVERAGEIF(Station_Visual_Nodes!$D:$D,B241,Station_Visual_Nodes!$I:$I),"") -> 3392 | G241: =IFERROR(AVERAGEIF(Station_Visual_Nodes!$D:$D,B241,Station_Visual_Nodes!$J:$J),"") -> 2652 | H241: =IF(F241="","",F241/Config!$B$2*100) -> 66.25 | I241: =IF(G241="","",G241/Config!$B$3*100) -> 92.083333 | J241: 24 | K241: circle | L241: auto_from_visual_nodes_avg

Sheet Station_Labels
A1: mark_status | B1: station_key | C1: station_name | D1: display_name | E1: available_lines | F1: label_x_px | G1: label_y_px | H1: label_x_pct | I1: label_y_pct | J1: label_size_px | K1: label_weight | L1: label_anchor | M1: label_rotation | N1: source_method | O1: memo
A2: =IF(OR(F2="",G2=""),"미작업","완료") -> 완료 | B2: 서울역 | C2: 서울역 | D2: 서울역 | E2: 1,4 | F2: =IFERROR(INDEX(Station_Click_Areas!$F:$F,MATCH(B2,Station_Click_Areas!$B:$B,0)),"") -> 1916 | G2: =IFERROR(INDEX(Station_Click_Areas!$G:$G,MATCH(B2,Station_Click_Areas!$B:$B,0)),"") -> 1308 | H2: =IF(F2="","",F2/Config!$B$2*100) -> 37.421875 | I2: =IF(G2="","",G2/Config!$B$3*100) -> 45.416667 | J2: 12 | K2: bold | L2: center | M2: 0 | N2: default_from_click_area
A3: =IF(OR(F3="",G3=""),"미작업","완료") -> 완료 | B3: 시청 | C3: 시청 | D3: 시청역 | E3: 1,2 | F3: =IFERROR(INDEX(Station_Click_Areas!$F:$F,MATCH(B3,Station_Click_Areas!$B:$B,0)),"") -> 1916 | G3: =IFERROR(INDEX(Station_Click_Areas!$G:$G,MATCH(B3,Station_Click_Areas!$B:$B,0)),"") -> 1144 | H3: =IF(F3="","",F3/Config!$B$2*100) -> 37.421875 | I3: =IF(G3="","",G3/Config!$B$3*100) -> 39.722222 | J3: 12 | K3: bold | L3: center | M3: 0 | N3: default_from_click_area
A4: =IF(OR(F4="",G4=""),"미작업","완료") -> 완료 | B4: 종각 | C4: 종각 | D4: 종각역 | E4: 1 | F4: =IFERROR(INDEX(Station_Click_Areas!$F:$F,MATCH(B4,Station_Click_Areas!$B:$B,0)),"") -> 1916 | G4: =IFERROR(INDEX(Station_Click_Areas!$G:$G,MATCH(B4,Station_Click_Areas!$B:$B,0)),"") -> 1048 | H4: =IF(F4="","",F4/Config!$B$2*100) -> 37.421875 | I4: =IF(G4="","",G4/Config!$B$3*100) -> 36.388889 | J4: 10.5 | K4: normal | L4: center | M4: 0 | N4: default_from_click_area
A5: =IF(OR(F5="",G5=""),"미작업","완료") -> 완료 | B5: 종로3가 | C5: 종로3가 | D5: 종로3가역 | E5: 1,3,5 | F5: =IFERROR(INDEX(Station_Click_Areas!$F:$F,MATCH(B5,Station_Click_Areas!$B:$B,0)),"") -> 2084 | G5: =IFERROR(INDEX(Station_Click_Areas!$G:$G,MATCH(B5,Station_Click_Areas!$B:$B,0)),"") -> 980 | H5: =IF(F5="","",F5/Config!$B$2*100) -> 40.703125 | I5: =IF(G5="","",G5/Config!$B$3*100) -> 34.027778 | J5: 13 | K5: bold | L5: center | M5: 0 | N5: default_from_click_area
A6: =IF(OR(F6="",G6=""),"미작업","완료") -> 완료 | B6: 종로5가 | C6: 종로5가 | D6: 종로5가역 | E6: 1 | F6: =IFERROR(INDEX(Station_Click_Areas!$F:$F,MATCH(B6,Station_Click_Areas!$B:$B,0)),"") -> 2240 | G6: =IFERROR(INDEX(Station_Click_Areas!$G:$G,MATCH(B6,Station_Click_Areas!$B:$B,0)),"") -> 980 | H6: =IF(F6="","",F6/Config!$B$2*100) -> 43.75 | I6: =IF(G6="","",G6/Config!$B$3*100) -> 34.027778 | J6: 10.5 | K6: normal | L6: center | M6: 0 | N6: default_from_click_area
A7: =IF(OR(F7="",G7=""),"미작업","완료") -> 완료 | B7: 동대문 | C7: 동대문 | D7: 동대문역 | E7: 1,4 | F7: =IFERROR(INDEX(Station_Click_Areas!$F:$F,MATCH(B7,Station_Click_Areas!$B:$B,0)),"") -> 2328 | G7: =IFERROR(INDEX(Station_Click_Areas!$G:$G,MATCH(B7,Station_Click_Areas!$B:$B,0)),"") -> 980 | H7: =IF(F7="","",F7/Config!$B$2*100) -> 45.46875 | I7: =IF(G7="","",G7/Config!$B$3*100) -> 34.027778 | J7: 12 | K7: bold | L7: center | M7: 0 | N7: default_from_click_area
A8: =IF(OR(F8="",G8=""),"미작업","완료") -> 완료 | B8: 동묘앞 | C8: 동묘앞 | D8: 동묘앞역 | E8: 1,6 | F8: =IFERROR(INDEX(Station_Click_Areas!$F:$F,MATCH(B8,Station_Click_Areas!$B:$B,0)),"") -> 2528 | G8: =IFERROR(INDEX(Station_Click_Areas!$G:$G,MATCH(B8,Station_Click_Areas!$B:$B,0)),"") -> 980 | H8: =IF(F8="","",F8/Config!$B$2*100) -> 49.375 | I8: =IF(G8="","",G8/Config!$B$3*100) -> 34.027778 | J8: 12 | K8: bold | L8: center | M8: 0 | N8: default_from_click_area
A9: =IF(OR(F9="",G9=""),"미작업","완료") -> 완료 | B9: 신설동 | C9: 신설동 | D9: 신설동역 | E9: 1,2 | F9: =IFERROR(INDEX(Station_Click_Areas!$F:$F,MATCH(B9,Station_Click_Areas!$B:$B,0)),"") -> 2712 | G9: =IFERROR(INDEX(Station_Click_Areas!$G:$G,MATCH(B9,Station_Click_Areas!$B:$B,0)),"") -> 980 | H9: =IF(F9="","",F9/Config!$B$2*100) -> 52.96875 | I9: =IF(G9="","",G9/Config!$B$3*100) -> 34.027778 | J9: 12 | K9: bold | L9: center | M9: 0 | N9: default_from_click_area
A10: =IF(OR(F10="",G10=""),"미작업","완료") -> 완료 | B10: 제기동 | C10: 제기동 | D10: 제기동역 | E10: 1 | F10: =IFERROR(INDEX(Station_Click_Areas!$F:$F,MATCH(B10,Station_Click_Areas!$B:$B,0)),"") -> 2864 | G10: =IFERROR(INDEX(Station_Click_Areas!$G:$G,MATCH(B10,Station_Click_Areas!$B:$B,0)),"") -> 980 | H10: =IF(F10="","",F10/Config!$B$2*100) -> 55.9375 | I10: =IF(G10="","",G10/Config!$B$3*100) -> 34.027778 | J10: 10.5 | K10: normal | L10: center | M10: 0 | N10: default_from_click_area
A11: =IF(OR(F11="",G11=""),"미작업","완료") -> 완료 | B11: 청량리 | C11: 청량리 | D11: 청량리역 | E11: 1 | F11: =IFERROR(INDEX(Station_Click_Areas!$F:$F,MATCH(B11,Station_Click_Areas!$B:$B,0)),"") -> 3020 | G11: =IFERROR(INDEX(Station_Click_Areas!$G:$G,MATCH(B11,Station_Click_Areas!$B:$B,0)),"") -> 980 | H11: =IF(F11="","",F11/Config!$B$2*100) -> 58.984375 | I11: =IF(G11="","",G11/Config!$B$3*100) -> 34.027778 | J11: 10.5 | K11: normal | L11: center | M11: 0 | N11: default_from_click_area
A12: =IF(OR(F12="",G12=""),"미작업","완료") -> 완료 | B12: 을지로입구 | C12: 을지로입구 | D12: 을지로입구역 | E12: 2 | F12: =IFERROR(INDEX(Station_Click_Areas!$F:$F,MATCH(B12,Station_Click_Areas!$B:$B,0)),"") -> 2000 | G12: =IFERROR(INDEX(Station_Click_Areas!$G:$G,MATCH(B12,Station_Click_Areas!$B:$B,0)),"") -> 1144 | H12: =IF(F12="","",F12/Config!$B$2*100) -> 39.0625 | I12: =IF(G12="","",G12/Config!$B$3*100) -> 39.722222 | J12: 10.5 | K12: normal | L12: center | M12: 0 | N12: default_from_click_area
A13: =IF(OR(F13="",G13=""),"미작업","완료") -> 완료 | B13: 을지로3가 | C13: 을지로3가 | D13: 을지로3가역 | E13: 2,3 | F13: =IFERROR(INDEX(Station_Click_Areas!$F:$F,MATCH(B13,Station_Click_Areas!$B:$B,0)),"") -> 2084 | G13: =IFERROR(INDEX(Station_Click_Areas!$G:$G,MATCH(B13,Station_Click_Areas!$B:$B,0)),"") -> 1144 | H13: =IF(F13="","",F13/Config!$B$2*100) -> 40.703125 | I13: =IF(G13="","",G13/Config!$B$3*100) -> 39.722222 | J13: 12 | K13: bold | L13: center | M13: 0 | N13: default_from_click_area
... A241: =IF(OR(F241="",G241=""),"미작업","완료") -> 완료 | B241: 모란 | C241: 모란 | D241: 모란역 | E241: 8 | F241: =IFERROR(INDEX(Station_Click_Areas!$F:$F,MATCH(B241,Station_Click_Areas!$B:$B,0)),"") -> 3392 | G241: =IFERROR(INDEX(Station_Click_Areas!$G:$G,MATCH(B241,Station_Click_Areas!$B:$B,0)),"") -> 2652 | H241: =IF(F241="","",F241/Config!$B$2*100) -> 66.25 | I241: =IF(G241="","",G241/Config!$B$3*100) -> 92.083333 | J241: 10.5 | K241: normal | L241: center | M241: 0 | N241: default_from_click_area

Sheet Line_Sequences
A1: line_id | B1: branch_code | C1: path_order | D1: visual_node_id | E1: station_key | F1: station_name | G1: display_name | H1: is_branch_endpoint | I1: alias_or_note
A2: 1 | B2: main | C2: 1 | D2: 서울역_L1 | E2: 서울역 | F2: 서울역 | G2: 서울역 | H2: TRUE
A3: 1 | B3: main | C3: 2 | D3: 시청_L1 | E3: 시청 | F3: 시청 | G3: 시청역 | H3: FALSE
A4: 1 | B4: main | C4: 3 | D4: 종각_L1 | E4: 종각 | F4: 종각 | G4: 종각역 | H4: FALSE
A5: 1 | B5: main | C5: 4 | D5: 종로3가_L1 | E5: 종로3가 | F5: 종로3가 | G5: 종로3가역 | H5: FALSE
A6: 1 | B6: main | C6: 5 | D6: 종로5가_L1 | E6: 종로5가 | F6: 종로5가 | G6: 종로5가역 | H6: FALSE
A7: 1 | B7: main | C7: 6 | D7: 동대문_L1 | E7: 동대문 | F7: 동대문 | G7: 동대문역 | H7: FALSE
A8: 1 | B8: main | C8: 7 | D8: 동묘앞_L1 | E8: 동묘앞 | F8: 동묘앞 | G8: 동묘앞역 | H8: FALSE
A9: 1 | B9: main | C9: 8 | D9: 신설동_L1 | E9: 신설동 | F9: 신설동 | G9: 신설동역 | H9: FALSE
A10: 1 | B10: main | C10: 9 | D10: 제기동_L1 | E10: 제기동 | F10: 제기동 | G10: 제기동역 | H10: FALSE
A11: 1 | B11: main | C11: 10 | D11: 청량리_L1 | E11: 청량리 | F11: 청량리 | G11: 청량리역 | H11: TRUE | I11: 청량리(서울시립대입구)
A12: 2 | B12: main | C12: 1 | D12: 시청_L2 | E12: 시청 | F12: 시청 | G12: 시청역 | H12: TRUE
A13: 2 | B13: main | C13: 2 | D13: 을지로입구_L2 | E13: 을지로입구 | F13: 을지로입구 | G13: 을지로입구역 | H13: FALSE
A14: 2 | B14: main | C14: 3 | D14: 을지로3가_L2 | E14: 을지로3가 | F14: 을지로3가 | G14: 을지로3가역 | H14: FALSE
A15: 2 | B15: main | C15: 4 | D15: 을지로4가_L2 | E15: 을지로4가 | F15: 을지로4가 | G15: 을지로4가역 | H15: FALSE
A16: 2 | B16: main | C16: 5 | D16: 동대문역사문화공원_L2 | E16: 동대문역사문화공원 | F16: 동대문역사문화공원 | G16: 동대문역사문화공원역 | H16: FALSE | I16: 동대문역사문화공원(DDP)
A17: 2 | B17: main | C17: 6 | D17: 신당_L2 | E17: 신당 | F17: 신당 | G17: 신당역 | H17: FALSE
A18: 2 | B18: main | C18: 7 | D18: 상왕십리_L2 | E18: 상왕십리 | F18: 상왕십리 | G18: 상왕십리역 | H18: FALSE
A19: 2 | B19: main | C19: 8 | D19: 왕십리_L2 | E19: 왕십리 | F19: 왕십리 | G19: 왕십리역 | H19: FALSE
A20: 2 | B20: main | C20: 9 | D20: 한양대_L2 | E20: 한양대 | F20: 한양대 | G20: 한양대역 | H20: FALSE
A21: 2 | B21: main | C21: 10 | D21: 뚝섬_L2 | E21: 뚝섬 | F21: 뚝섬 | G21: 뚝섬역 | H21: FALSE
A22: 2 | B22: main | C22: 11 | D22: 성수_L2 | E22: 성수 | F22: 성수 | G22: 성수역 | H22: FALSE
A23: 2 | B23: main | C23: 12 | D23: 건대입구_L2 | E23: 건대입구 | F23: 건대입구 | G23: 건대입구역 | H23: FALSE
A24: 2 | B24: main | C24: 13 | D24: 구의_L2 | E24: 구의 | F24: 구의 | G24: 구의역 | H24: FALSE
A25: 2 | B25: main | C25: 14 | D25: 강변_L2 | E25: 강변 | F25: 강변 | G25: 강변역 | H25: FALSE
A26: 2 | B26: main | C26: 15 | D26: 잠실나루_L2 | E26: 잠실나루 | F26: 잠실나루 | G26: 잠실나루역 | H26: FALSE
A27: 2 | B27: main | C27: 16 | D27: 잠실_L2 | E27: 잠실 | F27: 잠실 | G27: 잠실역 | H27: FALSE
A28: 2 | B28: main | C28: 17 | D28: 잠실새내_L2 | E28: 잠실새내 | F28: 잠실새내 | G28: 잠실새내역 | H28: FALSE
... A72: 3 | B72: main | C72: 8 | D72: 독립문_L3 | E72: 독립문 | F72: 독립문 | G72: 독립문역 | H72: FALSE
A73: 3 | B73: main | C73: 9 | D73: 경복궁_L3 | E73: 경복궁 | F73: 경복궁 | G73: 경복궁역 | H73: FALSE | I73: 경복궁(정부서울청사)
A74: 3 | B74: main | C74: 10 | D74: 안국_L3 | E74: 안국 | F74: 안국 | G74: 안국역 | H74: FALSE
A75: 3 | B75: main | C75: 11 | D75: 종로3가_L3 | E75: 종로3가 | F75: 종로3가 | G75: 종로3가역 | H75: FALSE
A76: 3 | B76: main | C76: 12 | D76: 을지로3가_L3 | E76: 을지로3가 | F76: 을지로3가 | G76: 을지로3가역 | H76: FALSE
A77: 3 | B77: main | C77: 13 | D77: 충무로_L3 | E77: 충무로 | F77: 충무로 | G77: 충무로역 | H77: FALSE
A78: 3 | B78: main | C78: 14 | D78: 동대입구_L3 | E78: 동대입구 | F78: 동대입구 | G78: 동대입구역 | H78: FALSE
A79: 3 | B79: main | C79: 15 | D79: 약수_L3 | E79: 약수 | F79: 약수 | G79: 약수역 | H79: FALSE
A80: 3 | B80: main | C80: 16 | D80: 금호_L3 | E80: 금호 | F80: 금호 | G80: 금호역 | H80: FALSE
A81: 3 | B81: main | C81: 17 | D81: 옥수_L3 | E81: 옥수 | F81: 옥수 | G81: 옥수역 | H81: FALSE
A82: 3 | B82: main | C82: 18 | D82: 압구정_L3 | E82: 압구정 | F82: 압구정 | G82: 압구정역 | H82: FALSE
A83: 3 | B83: main | C83: 19 | D83: 신사_L3 | E83: 신사 | F83: 신사 | G83: 신사역 | H83: FALSE
...

Sheet Transfer_Links
A1: station_key | B1: station_name | C1: from_line_id | D1: to_line_id | E1: from_visual_node_id | F1: to_visual_node_id | G1: transfer_style | H1: connector_visible | I1: connector_color | J1: memo
A2: 서울역 | B2: 서울역 | C2: 1 | D2: 4 | E2: 서울역_L1 | F2: 서울역_L4 | G2: connector | H2: TRUE | I2: #9CA3AF | J2: 지도 렌더링용 환승 연결선; 실제 환승 시간/거리 평가는 별도 환승 데이터 사용
A3: 시청 | B3: 시청 | C3: 1 | D3: 2 | E3: 시청_L1 | F3: 시청_L2 | G3: connector | H3: TRUE | I3: #9CA3AF | J3: 지도 렌더링용 환승 연결선; 실제 환승 시간/거리 평가는 별도 환승 데이터 사용
A4: 종로3가 | B4: 종로3가 | C4: 1 | D4: 3 | E4: 종로3가_L1 | F4: 종로3가_L3 | G4: connector | H4: TRUE | I4: #9CA3AF | J4: 지도 렌더링용 환승 연결선; 실제 환승 시간/거리 평가는 별도 환승 데이터 사용
A5: 종로3가 | B5: 종로3가 | C5: 1 | D5: 5 | E5: 종로3가_L1 | F5: 종로3가_L5 | G5: connector | H5: TRUE | I5: #9CA3AF | J5: 지도 렌더링용 환승 연결선; 실제 환승 시간/거리 평가는 별도 환승 데이터 사용
A6: 종로3가 | B6: 종로3가 | C6: 3 | D6: 5 | E6: 종로3가_L3 | F6: 종로3가_L5 | G6: connector | H6: TRUE | I6: #9CA3AF | J6: 지도 렌더링용 환승 연결선; 실제 환승 시간/거리 평가는 별도 환승 데이터 사용
A7: 동대문 | B7: 동대문 | C7: 1 | D7: 4 | E7: 동대문_L1 | F7: 동대문_L4 | G7: connector | H7: TRUE | I7: #9CA3AF | J7: 지도 렌더링용 환승 연결선; 실제 환승 시간/거리 평가는 별도 환승 데이터 사용
A8: 동묘앞 | B8: 동묘앞 | C8: 1 | D8: 6 | E8: 동묘앞_L1 | F8: 동묘앞_L6 | G8: connector | H8: TRUE | I8: #9CA3AF | J8: 지도 렌더링용 환승 연결선; 실제 환승 시간/거리 평가는 별도 환승 데이터 사용
A9: 신설동 | B9: 신설동 | C9: 1 | D9: 2 | E9: 신설동_L1 | F9: 신설동_L2 | G9: connector | H9: TRUE | I9: #9CA3AF | J9: 지도 렌더링용 환승 연결선; 실제 환승 시간/거리 평가는 별도 환승 데이터 사용
A10: 을지로3가 | B10: 을지로3가 | C10: 2 | D10: 3 | E10: 을지로3가_L2 | F10: 을지로3가_L3 | G10: connector | H10: TRUE | I10: #9CA3AF | J10: 지도 렌더링용 환승 연결선; 실제 환승 시간/거리 평가는 별도 환승 데이터 사용
A11: 을지로4가 | B11: 을지로4가 | C11: 2 | D11: 5 | E11: 을지로4가_L2 | F11: 을지로4가_L5 | G11: connector | H11: TRUE | I11: #9CA3AF | J11: 지도 렌더링용 환승 연결선; 실제 환승 시간/거리 평가는 별도 환승 데이터 사용
A12: 동대문역사문화공원 | B12: 동대문역사문화공원 | C12: 2 | D12: 4 | E12: 동대문역사문화공원_L2 | F12: 동대문역사문화공원_L4 | G12: connector | H12: TRUE | I12: #9CA3AF | J12: 지도 렌더링용 환승 연결선; 실제 환승 시간/거리 평가는 별도 환승 데이터 사용
A13: 동대문역사문화공원 | B13: 동대문역사문화공원 | C13: 2 | D13: 5 | E13: 동대문역사문화공원_L2 | F13: 동대문역사문화공원_L5 | G13: connector | H13: TRUE | I13: #9CA3AF | J13: 지도 렌더링용 환승 연결선; 실제 환승 시간/거리 평가는 별도 환승 데이터 사용
... A40: 태릉입구 | B40: 태릉입구 | C40: 6 | D40: 7 | E40: 태릉입구_L6 | F40: 태릉입구_L7 | G40: connector | H40: TRUE | I40: #9CA3AF | J40: 지도 렌더링용 환승 연결선; 실제 환승 시간/거리 평가는 별도 환승 데이터 사용

Sheet Map_Layer_Order
A1: layer_order | B1: layer_name | C1: source_sheet | D1: render_object | E1: note
A2: 1 | B2: line_paths | C2: Line_Sequences + Station_Visual_Nodes | D2: polyline/path | E2: 노선별 visual_node_id 좌표를 path_order 순서로 연결
A3: 2 | B3: transfer_connectors | C3: Transfer_Links | D3: line/path | E3: 환승역의 노선별 visual node를 얇은 회색 연결선으로 연결
A4: 3 | B4: station_markers | C4: Station_Visual_Nodes | D4: circle | E4: 지도에 보이는 역 점. 환승역은 노선별로 여러 점 가능
A5: 4 | B5: station_labels | C5: Station_Labels | D5: text | E5: 역명 라벨. station_key 기준으로 역당 1개 권장
A6: 5 | B6: route_highlight | C6: routing result | D6: path overlay | E6: 추천 경로 구간만 굵게 강조
A7: 6 | B7: origin_destination_highlight | C7: session_state | D7: halo/circle | E7: 출발역/도착역 강조
A8: 7 | B8: click_hitboxes | C8: Station_Click_Areas | D8: transparent circle | E8: 사용자 클릭 판정. 보이는 점보다 큰 투명 영역

Sheet Project_Scope
A1: line_id | B1: branch_code | C1: start_station | D1: end_station | E1: project_range | F1: note
A2: 1 | B2: main | C2: 서울역 | D2: 청량리 | E2: 서울역~청량리역 | F2: 서울교통공사 1호선 도심 구간
A3: 2 | B3: main | C3: 전구간 | D3: 전구간 | E3: 순환선 전구간 | F3: 성수지선·신정지선은 별도 branch row로 관리
A4: 2 | B4: seongsu_branch | C4: 성수 | D4: 신설동 | E4: 성수~신설동 | F4: 성수지선
A5: 2 | B5: sinjeong_branch | C5: 신도림 | D5: 까치산 | E5: 신도림~까치산 | F5: 신정지선
A6: 3 | B6: main | C6: 지축 | D6: 오금 | E6: 지축역~오금역
A7: 4 | B7: main | C7: 불암산 | D7: 남태령 | E7: 불암산역~남태령역 | F7: 불암산=구 당고개
A8: 5 | B8: common | C8: 방화 | D8: 강동 | E8: 방화역~강동역 | F8: 하남/마천 분기 전 공통 구간
A9: 5 | B9: hanam_branch | C9: 강동 | D9: 하남검단산 | E9: 강동역~하남검단산역
A10: 5 | B10: macheon_branch | C10: 강동 | D10: 마천 | E10: 강동역~마천역
A11: 6 | B11: main | C11: 응암 | D11: 신내 | E11: 응암역~신내역 | F11: 응암순환 구조는 노선도/라우팅에서 별도 주의
A12: 7 | B12: main | C12: 장암 | D12: 온수 | E12: 장암역~온수역
A13: 8 | B13: main | C13: 암사역사공원 | D13: 모란 | E13: 암사역사공원역~모란역 | F13: 남위례 포함

Sheet AI_Handoff_Prompt
A1: 이 파일은 MetroCalm 벡터형 클릭 노선도 제작용 좌표 워크북입니다.
A2: 핵심 구조: Station_Display_Master=사용자 선택용 역 단위, Station_Visual_Nodes=노선별 지도 렌더링 좌표, Station_Click_Areas=투명 클릭 hitbox, Station_Labels=역명 좌표, Line_Sequences=노선 연결 순서, Transfer_Links=환승 연결선.
A3: Station_Visual_Nodes의 x_px, y_px가 최우선 수작업 입력 대상입니다. 환승역은 노선별 visual_node_id 좌표를 분리해서 선이 겹치지 않게 합니다.
A4: Station_Click_Areas는 visual node 평균 좌표로 자동 생성되며, 복잡한 환승역만 click_x_px, click_y_px, click_radius_px를 수동 보정합니다. 클릭 영역은 보이지 않는 투명 원으로 최상단에 둡니다.
A5: Station_Labels는 station_key 기준으로 역명을 한 번만 표시합니다. label 좌표는 자동값을 시작점으로 쓰고, 겹치는 역명만 수동 보정합니다.
A6: 사용자 클릭/입력은 station_key 기준입니다. 지도 렌더링은 visual_node_id 기준입니다. 내부 라우팅은 기존 station_uid 기준입니다. 사용자 화면에 station_uid와 visual_node_id를 노출하지 않습니다.
A7: SVG로 만들 경우 viewBox="0 0 4900 2757"을 기본 좌표계로 사용하고, x_px/y_px를 그대로 circle/path/text 좌표로 사용합니다. 이미지 크기 변경 시 Config 값을 기준으로 pct 좌표를 재계산합니다.
A8: Line_Sequences는 visual_node_id를 path_order 순서로 이어 노선 path를 만듭니다. Transfer_Links는 같은 station_key의 서로 다른 line visual node를 얇은 connector로 연결합니다.
A9: 추천 경로가 나오면 station_uid path를 station_key/visual_node_id path로 변환하고, 해당 Line_Sequences segment를 굵은 overlay로 highlight합니다.
A10: 서울역→강남역 regression test: 서울역은 1호선/4호선 후보를 모두 비교하며, 최초 노선 선택은 환승으로 계산하지 않습니다.

Sheet Sources
A1: source_name | B1: url | C1: usage_note
A2: 서울교통공사_자치구별지하철역정보 | B2: https://www.data.go.kr/data/15081868/fileData.do | C2: 서울교통공사 관리 역 정보의 공식 공공데이터. 역명/호선 검증 참고.
A3: 서울교통공사_역간거리 | B3: https://data.seoul.go.kr/dataList/OA-12034/S/1/datasetView.do | C3: 서울교통공사 1~8호선 역간 거리 및 소요시간 데이터. 노선 순서/연결 검증 참고.
A4: 사용자 지정 프로젝트 범위 | B4: 현재 대화에서 사용자가 제공한 프로젝트 구간 | C4: 본 워크북은 사용자가 제공한 MetroCalm 프로젝트 범위에 맞춰 역 목록을 정리함.
A5: workbook_basis | B5: previous metrocalm_project_station_click_points.xlsx | C5: 프로젝트 구간 역 목록과 Line_Sequences를 기반으로 재구성
A6: coordinate_image_basis | B6: user-provided 4900x2757 subway map reference | C6: 좌표 입력 기준 이미지 크기
